<sdf version="1.7">
  <world name="default">
    <light name="sun" type="directional">
      <cast_shadows>1</cast_shadows>
      <pose>0 0 10 0 -0 0</pose>
      <diffuse>0.8 0.8 0.8 1</diffuse>
      <specular>0.2 0.2 0.2 1</specular>
      <attenuation>
        <range>1000</range>
        <constant>0.9</constant>
        <linear>0.01</linear>
        <quadratic>0.001</quadratic>
      </attenuation>
      <direction>-0.5 0.1 -0.9</direction>
      <spot>
        <inner_angle>0</inner_angle>
        <outer_angle>0</outer_angle>
        <falloff>0</falloff>
      </spot>
    </light>
    <model name="ground_plane">
      <static>1</static>
      <link name="link">
        <collision name="collision">
          <geometry>
            <plane>
              <normal>0 0 1</normal>
              <size>100 100</size>
            </plane>
          </geometry>
          <surface>
            <friction>
              <ode>
                <mu>100</mu>
                <mu2>50</mu2>
              </ode>
              <torsional>
                <ode/>
              </torsional>
            </friction>
            <contact>
              <ode/>
            </contact>
            <bounce/>
          </surface>
          <max_contacts>10</max_contacts>
        </collision>
        <visual name="visual">
          <cast_shadows>0</cast_shadows>
          <geometry>
            <plane>
              <normal>0 0 1</normal>
              <size>100 100</size>
            </plane>
          </geometry>
          <material>
            <script>
              <uri>file://media/materials/scripts/gazebo.material</uri>
              <name>Gazebo/Grey</name>
            </script>
          </material>
        </visual>
        <self_collide>0</self_collide>
        <enable_wind>0</enable_wind>
        <kinematic>0</kinematic>
      </link>
    </model>
    <gravity>0 0 -9.8</gravity>
    <magnetic_field>6e-06 2.3e-05 -4.2e-05</magnetic_field>
    <atmosphere type="adiabatic"/>
    <physics type="ode">
      <max_step_size>0.001</max_step_size>
      <real_time_factor>1</real_time_factor>
      <real_time_update_rate>1000</real_time_update_rate>
    </physics>
    <scene>
      <ambient>0.4 0.4 0.4 1</ambient>
      <background>0.7 0.7 0.7 1</background>
      <shadows>1</shadows>
    </scene>
    <audio>
      <device>default</device>
    </audio>
    <wind/>
    <spherical_coordinates>
      <surface_model>EARTH_WGS84</surface_model>
      <latitude_deg>0</latitude_deg>
      <longitude_deg>0</longitude_deg>
      <elevation>0</elevation>
      <heading_deg>0</heading_deg>
    </spherical_coordinates>
    <model name="ur5">
      <joint name="world_to_base" type="fixed">
        <pose relative_to="__model__">0 0 0 0 -0 0</pose>
        <parent>world</parent>
        <child>base_link</child>
      </joint>
      <link name="base_link">
        <pose relative_to="world_to_base">0 0 0 0 -0 0</pose>
        <inertial>
          <pose>-0.000367 -0.000368 0.016561 0 -0 0</pose>
          <mass>4</mass>
          <inertia>
            <ixx>0.00060258</ixx>
            <ixy>1.7502e-05</ixy>
            <ixz>1.5277e-06</ixz>
            <iyy>0.00060261</iyy>
            <iyz>1.5241e-06</iyz>
            <izz>0.0010709</izz>
          </inertia>
        </inertial>
        <collision name="base_link_collision">
          <pose>0 0 0 0 -0 0</pose>
          <geometry>
            <mesh>
              <scale>1 1 1</scale>
              <uri>/home/ps/dof_6_ws/src/ur5/meshes/base_link.STL</uri>
            </mesh>
          </geometry>
          <surface>
            <contact>
              <ode/>
            </contact>
            <friction>
              <ode/>
              <torsional>
                <ode/>
              </torsional>
            </friction>
            <bounce/>
          </surface>
          <max_contacts>10</max_contacts>
        </collision>
        <visual name="base_link_visual">
          <pose>0 0 0 0 -0 0</pose>
          <geometry>
            <mesh>
              <scale>1 1 1</scale>
              <uri>/home/ps/dof_6_ws/src/ur5/meshes/base_link.STL</uri>
            </mesh>
          </geometry>
          <material>
            <script>
              <name>Gazebo/Yellow</name>
              <uri>file://media/materials/scripts/gazebo.material</uri>
            </script>
          </material>
        </visual>
        <self_collide>0</self_collide>
        <enable_wind>0</enable_wind>
        <kinematic>0</kinematic>
      </link>
      <joint name="shoulder_pan_joint" type="revolute">
        <pose relative_to="base_link">0 0 0.009992 -1.57079 1.57079 3.14159</pose>
        <parent>base_link</parent>
        <child>shoulder_link</child>
        <axis>
          <xyz>1 0 0</xyz>
          <limit>
            <lower>-6.2832</lower>
            <upper>6.2832</upper>
            <effort>300</effort>
            <velocity>3</velocity>
          </limit>
          <dynamics>
            <damping>10</damping>
            <friction>1</friction>
            <spring_reference>0</spring_reference>
            <spring_stiffness>0</spring_stiffness>
          </dynamics>
        </axis>
      </joint>
      <link name="shoulder_link">
        <pose relative_to="shoulder_pan_joint">0 0 0 0 -0 0</pose>
        <inertial>
          <pose>-0.078966 0.016439 -6e-06 0 -0 0</pose>
          <mass>3.7</mass>
          <inertia>
            <ixx>0.0028298</ixx>
            <ixy>0.00031932</ixy>
            <ixz>-1.3132e-07</ixz>
            <iyy>0.002538</iyy>
            <iyz>4.4907e-07</iyz>
            <izz>0.0026207</izz>
          </inertia>
        </inertial>
        <collision name="shoulder_link_collision">
          <pose>0 0 0 0 -0 0</pose>
          <geometry>
            <mesh>
              <scale>1 1 1</scale>
              <uri>/home/ps/dof_6_ws/src/ur5/meshes/shoulder_link.STL</uri>
            </mesh>
          </geometry>
          <surface>
            <contact>
              <ode/>
            </contact>
            <friction>
              <ode/>
              <torsional>
                <ode/>
              </torsional>
            </friction>
            <bounce/>
          </surface>
          <max_contacts>10</max_contacts>
        </collision>
        <visual name="shoulder_link_visual">
          <pose>0 0 0 0 -0 0</pose>
          <geometry>
            <mesh>
              <scale>1 1 1</scale>
              <uri>/home/ps/dof_6_ws/src/ur5/meshes/shoulder_link.STL</uri>
            </mesh>
          </geometry>
          <material>
            <script>
              <name>Gazebo/Yellow</name>
              <uri>file://media/materials/scripts/gazebo.material</uri>
            </script>
          </material>
        </visual>
        <self_collide>1</self_collide>
        <enable_wind>0</enable_wind>
        <kinematic>0</kinematic>
      </link>
      <joint name="shoulder_lift_joint" type="revolute">
        <pose relative_to="shoulder_link">-0.080008 0.053821 0 0 -0 0</pose>
        <parent>shoulder_link</parent>
        <child>upper_arm_link</child>
        <axis>
          <xyz>0 -1 0</xyz>
          <limit>
            <lower>-6.2832</lower>
            <upper>6.2832</upper>
            <effort>200</effort>
            <velocity>3</velocity>
          </limit>
          <dynamics>
            <damping>10</damping>
            <friction>1</friction>
            <spring_reference>0</spring_reference>
            <spring_stiffness>0</spring_stiffness>
          </dynamics>
        </axis>
      </joint>
      <link name="upper_arm_link">
        <pose relative_to="shoulder_lift_joint">0 0 0 0 -0 0</pose>
        <inertial>
          <pose>-0.21652 0.079293 0 0 -0 0</pose>
          <mass>8.393</mass>
          <inertia>
            <ixx>0.0063671</ixx>
            <ixy>-9.2154e-12</ixy>
            <ixz>9.0018e-07</ixz>
            <iyy>0.021824</iyy>
            <iyz>-2.2572e-07</iyz>
            <izz>0.021327</izz>
          </inertia>
        </inertial>
        <collision name="upper_arm_link_collision">
          <pose>0 0 0 0 -0 0</pose>
          <geometry>
            <mesh>
              <scale>1 1 1</scale>
              <uri>/home/ps/dof_6_ws/src/ur5/meshes/upper_arm_link.STL</uri>
            </mesh>
          </geometry>
          <surface>
            <contact>
              <ode/>
            </contact>
            <friction>
              <ode/>
              <torsional>
                <ode/>
              </torsional>
            </friction>
            <bounce/>
          </surface>
          <max_contacts>10</max_contacts>
        </collision>
        <visual name="upper_arm_link_visual">
          <pose>0 0 0 0 -0 0</pose>
          <geometry>
            <mesh>
              <scale>1 1 1</scale>
              <uri>/home/ps/dof_6_ws/src/ur5/meshes/upper_arm_link.STL</uri>
            </mesh>
          </geometry>
          <material>
            <script>
              <name>Gazebo/White</name>
              <uri>file://media/materials/scripts/gazebo.material</uri>
            </script>
          </material>
        </visual>
        <self_collide>1</self_collide>
        <enable_wind>0</enable_wind>
        <kinematic>0</kinematic>
      </link>
      <joint name="elbow_joint" type="revolute">
        <pose relative_to="upper_arm_link">-0.425 0 0 0 -0 0</pose>
        <parent>upper_arm_link</parent>
        <child>forearm_link</child>
        <axis>
          <xyz>0 1 0</xyz>
          <limit>
            <lower>-6.2832</lower>
            <upper>6.2832</upper>
            <effort>200</effort>
            <velocity>3</velocity>
          </limit>
          <dynamics>
            <damping>10</damping>
            <friction>1</friction>
            <spring_reference>0</spring_reference>
            <spring_stiffness>0</spring_stiffness>
          </dynamics>
        </axis>
      </joint>
      <link name="forearm_link">
        <pose relative_to="elbow_joint">0 0 0 0 -0 0</pose>
        <inertial>
          <pose>-0.1739 -0.033049 -3e-06 0 -0 0</pose>
          <mass>2.275</mass>
          <inertia>
            <ixx>0.002241</ixx>
            <ixy>-0.00011285</ixy>
            <ixz>4.2229e-07</ixz>
            <iyy>0.011808</iyy>
            <iyz>-2.6928e-07</iyz>
            <izz>0.011655</izz>
          </inertia>
        </inertial>
        <collision name="forearm_link_collision">
          <pose>0 0 0 0 -0 0</pose>
          <geometry>
            <mesh>
              <scale>1 1 1</scale>
              <uri>/home/ps/dof_6_ws/src/ur5/meshes/forearm_link.STL</uri>
            </mesh>
          </geometry>
          <surface>
            <contact>
              <ode/>
            </contact>
            <friction>
              <ode/>
              <torsional>
                <ode/>
              </torsional>
            </friction>
            <bounce/>
          </surface>
          <max_contacts>10</max_contacts>
        </collision>
        <visual name="forearm_link_visual">
          <pose>0 0 0 0 -0 0</pose>
          <geometry>
            <mesh>
              <scale>1 1 1</scale>
              <uri>/home/ps/dof_6_ws/src/ur5/meshes/forearm_link.STL</uri>
            </mesh>
          </geometry>
          <material>
            <script>
              <name>Gazebo/White</name>
              <uri>file://media/materials/scripts/gazebo.material</uri>
            </script>
          </material>
        </visual>
        <self_collide>1</self_collide>
        <enable_wind>0</enable_wind>
        <kinematic>0</kinematic>
      </link>
      <joint name="wrist_1_joint" type="revolute">
        <pose relative_to="forearm_link">-0.39225 0 0 0 -0 0</pose>
        <parent>forearm_link</parent>
        <child>wrist_1_link</child>
        <axis>
          <xyz>0 -1 0</xyz>
          <limit>
            <lower>-6.2832</lower>
            <upper>6.2832</upper>
            <effort>200</effort>
            <velocity>3</velocity>
          </limit>
          <dynamics>
            <damping>10</damping>
            <friction>1</friction>
            <spring_reference>0</spring_reference>
            <spring_stiffness>0</spring_stiffness>
          </dynamics>
        </axis>
      </joint>
      <link name="wrist_1_link">
        <pose relative_to="wrist_1_joint">0 0 0 0 -0 0</pose>
        <inertial>
          <pose>0.003753 0.044978 1.3e-05 0 -0 0</pose>
          <mass>1.219</mass>
          <inertia>
            <ixx>0.00041141</ixx>
            <ixy>4.2784e-05</ixy>
            <ixz>-2.8598e-07</ixz>
            <iyy>0.00036744</iyy>
            <iyz>4.089e-07</iyz>
            <izz>0.000387</izz>
          </inertia>
        </inertial>
        <collision name="wrist_1_link_collision">
          <pose>0 0 0 0 -0 0</pose>
          <geometry>
            <mesh>
              <scale>1 1 1</scale>
              <uri>/home/ps/dof_6_ws/src/ur5/meshes/wrist_1_link.STL</uri>
            </mesh>
          </geometry>
          <surface>
            <contact>
              <ode/>
            </contact>
            <friction>
              <ode/>
              <torsional>
                <ode/>
              </torsional>
            </friction>
            <bounce/>
          </surface>
          <max_contacts>10</max_contacts>
        </collision>
        <visual name="wrist_1_link_visual">
          <pose>0 0 0 0 -0 0</pose>
          <geometry>
            <mesh>
              <scale>1 1 1</scale>
              <uri>/home/ps/dof_6_ws/src/ur5/meshes/wrist_1_link.STL</uri>
            </mesh>
          </geometry>
          <material>
            <script>
              <name>Gazebo/White</name>
              <uri>file://media/materials/scripts/gazebo.material</uri>
            </script>
          </material>
        </visual>
        <self_collide>1</self_collide>
        <enable_wind>0</enable_wind>
        <kinematic>0</kinematic>
      </link>
      <joint name="wrist_2_joint" type="revolute">
        <pose relative_to="wrist_1_link">0 0.056149 0 0 -0 0</pose>
        <parent>wrist_1_link</parent>
        <child>wrist_2_link</child>
        <axis>
          <xyz>1 0 0</xyz>
          <limit>
            <lower>-6.2832</lower>
            <upper>6.2832</upper>
            <effort>200</effort>
            <velocity>3</velocity>
          </limit>
          <dynamics>
            <damping>10</damping>
            <friction>1</friction>
            <spring_reference>0</spring_reference>
            <spring_stiffness>0</spring_stiffness>
          </dynamics>
        </axis>
      </joint>
      <link name="wrist_2_link">
        <pose relative_to="wrist_2_joint">0 0 0 0 -0 0</pose>
        <inertial>
          <pose>-0.083749 -0.003753 -1.2e-05 0 -0 0</pose>
          <mass>1.219</mass>
          <inertia>
            <ixx>0.00036744</ixx>
            <ixy>4.2782e-05</ixy>
            <ixz>4.1013e-07</ixz>
            <iyy>0.0004114</iyy>
            <iyz>-2.8709e-07</iyz>
            <izz>0.000387</izz>
          </inertia>
        </inertial>
        <collision name="wrist_2_link_collision">
          <pose>0 0 0 0 -0 0</pose>
          <geometry>
            <mesh>
              <scale>1 1 1</scale>
              <uri>/home/ps/dof_6_ws/src/ur5/meshes/wrist_2_link.STL</uri>
            </mesh>
          </geometry>
          <surface>
            <contact>
              <ode/>
            </contact>
            <friction>
              <ode/>
              <torsional>
                <ode/>
              </torsional>
            </friction>
            <bounce/>
          </surface>
          <max_contacts>10</max_contacts>
        </collision>
        <visual name="wrist_2_link_visual">
          <pose>0 0 0 0 -0 0</pose>
          <geometry>
            <mesh>
              <scale>1 1 1</scale>
              <uri>/home/ps/dof_6_ws/src/ur5/meshes/wrist_2_link.STL</uri>
            </mesh>
          </geometry>
          <material>
            <script>
              <name>Gazebo/White</name>
              <uri>file://media/materials/scripts/gazebo.material</uri>
            </script>
          </material>
        </visual>
        <self_collide>1</self_collide>
        <enable_wind>0</enable_wind>
        <kinematic>0</kinematic>
      </link>
      <joint name="wrist_3_joint" type="revolute">
        <pose relative_to="wrist_2_link">-0.09492 0.041547 0 -3.14159 -0 -3.14159</pose>
        <parent>wrist_2_link</parent>
        <child>wrist_3_link</child>
        <axis>
          <xyz>0 -1 0</xyz>
          <limit>
            <lower>-6.2832</lower>
            <upper>6.2832</upper>
            <effort>200</effort>
            <velocity>3</velocity>
          </limit>
          <dynamics>
            <damping>10</damping>
            <friction>1</friction>
            <spring_reference>0</spring_reference>
            <spring_stiffness>0</spring_stiffness>
          </dynamics>
        </axis>
      </joint>
      <link name="wrist_3_link">
        <pose relative_to="wrist_3_joint">0 0 0 0 -0 0</pose>
        <inertial>
          <pose>-7.6e-05 0.018179 0.00012 0 -0 0</pose>
          <mass>0.18791</mass>
          <inertia>
            <ixx>6.9269e-05</ixx>
            <ixy>5.70242e-08</ixy>
            <ixz>-3.20042e-07</ixz>
            <iyy>0.000117056</iyy>
            <iyz>-8.83978e-08</iyz>
            <izz>6.95671e-05</izz>
          </inertia>
        </inertial>
        <collision name="wrist_3_link_collision">
          <pose>0 0 0 0 -0 0</pose>
          <geometry>
            <mesh>
              <scale>1 1 1</scale>
              <uri>/home/ps/dof_6_ws/src/ur5/meshes/wrist_3_link.STL</uri>
            </mesh>
          </geometry>
          <surface>
            <contact>
              <ode/>
            </contact>
            <friction>
              <ode/>
              <ode/>
              <torsional>
                <ode/>
              </torsional>
              <mu>100</mu>
              <mu2>100</mu2>
            </friction>
            <bounce/>
          </surface>
          <max_contacts>10</max_contacts>
        </collision>
        <!-- <collision name="wrist_3_link_fixed_joint_lump__camera_link_collision_1">
          <pose>0.03 0.04 0 0 -0 1.508</pose>
          <geometry>
            <box>
              <size>0.01 0.01 0.01</size>
            </box>
          </geometry>
          <surface>
            <contact>
              <ode/>
            </contact>
            <friction>
              <ode/>
              <torsional>
                <ode/>
              </torsional>
            </friction>
            <bounce/>
          </surface>
          <max_contacts>10</max_contacts>
        </collision> -->
        <visual name="wrist_3_link_visual">
          <pose>0 0 0 0 -0 0</pose>
          <geometry>
            <mesh>
              <scale>1 1 1</scale>
              <uri>/home/ps/dof_6_ws/src/ur5/meshes/wrist_3_link.STL</uri>
            </mesh>
          </geometry>
          <material>
            <script>
              <name>Gazebo/Red</name>
              <uri>file://media/materials/scripts/gazebo.material</uri>
            </script>
          </material>
        </visual>
        <visual name="wrist_3_link_fixed_joint_lump__camera_link_visual_1">
          <pose>0.03 0.04 0 0 -0 1.508</pose>
          <geometry>
            <box>
              <size>0.01 0.01 0.01</size>
            </box>
          </geometry>
          <material>
            <script>
              <name>Gazebo/Black</name>
              <uri>file://media/materials/scripts/gazebo.material</uri>
            </script>
          </material>
        </visual>
        <self_collide>1</self_collide>
        <sensor name="camera1" type="camera">
          <update_rate>30</update_rate>
          <camera name="head">
            <horizontal_fov>1.39626</horizontal_fov>
            <image>
              <width>1080</width>
              <height>720</height>
              <format>B8G8R8</format>
            </image>
            <clip>
              <near>0.02</near>
              <far>300</far>
            </clip>
            <noise>
              <type>gaussian</type>
              <mean>0</mean>
              <stddev>0.007</stddev>
            </noise>
          </camera>
          <plugin name="camera_controller" filename="libgazebo_ros_camera.so">
            <alwaysOn>1</alwaysOn>
            <updateRate>0.0</updateRate>
            <cameraName>ur5/usbcam</cameraName>
            <imageTopicName>image_raw</imageTopicName>
            <cameraInfoTopicName>camera_info</cameraInfoTopicName>
            <frameName>camera_link_optical</frameName>
          </plugin>
          <pose>0.03 0.04 0 0 -0 1.508</pose>
        </sensor>
        <enable_wind>0</enable_wind>
        <kinematic>0</kinematic>
      </link>
      <joint name="gripper_joint1" type="revolute">
        <pose relative_to="wrist_3_link">0 0.04 0 1.57 -0 0</pose>
        <parent>wrist_3_link</parent>
        <child>vacuum_gripper1</child>
        <axis>
          <xyz>1 0 0</xyz>
          <limit>
            <lower>0</lower>
            <upper>0</upper>
            <effort>100</effort>
            <velocity>20</velocity>
          </limit>
          <dynamics>
            <damping>0</damping>
            <friction>1000</friction>
            <spring_reference>0</spring_reference>
            <spring_stiffness>0</spring_stiffness>
          </dynamics>
        </axis>
      </joint>
      <link name="vacuum_gripper1">
        <pose relative_to="gripper_joint1">0 0 0 0 -0 0</pose>
        <inertial>
          <pose>0 0 0 0 -0 0</pose>
          <mass>0.0001</mass>
          <inertia>
            <ixx>1e-08</ixx>
            <ixy>0</ixy>
            <ixz>0</ixz>
            <iyy>1e-08</iyy>
            <iyz>0</iyz>
            <izz>1e-08</izz>
          </inertia>
        </inertial>
        <visual name="vacuum_gripper1_visual">
          <pose>0 0 0 0 -0 0</pose>
          <geometry>
            <cylinder>
              <length>0.015</length>
              <radius>0.02</radius>
            </cylinder>
          </geometry>
          <material>
            <script>
              <name>Gazebo/Black</name>
              <uri>file://media/materials/scripts/gazebo.material</uri>
            </script>
          </material>
        </visual>
        <self_collide>0</self_collide>
        <enable_wind>0</enable_wind>
        <kinematic>0</kinematic>
      </link>
      <plugin name="gazebo_ros_vacuum_gripper1" filename="libgazebo_ros_vacuum_gripper.so">
        <robotNamespace>/ur5/vacuum_gripper1</robotNamespace>
        <link_name>vacuum_gripper1</link_name>
        <bodyName>vacuum_gripper1</bodyName>
        <topicName>grasping1</topicName>
        <maxForce>1000000</maxForce>
        <maxDistance>0.05</maxDistance>
        <minDistance>0.01</minDistance>
      </plugin>
      <static>0</static>
      <plugin name="gazebo_ros2_control" filename="libgazebo_ros2_control.so">
        <robot_sim_type>gazebo_ros2_control/GazeboSystem</robot_sim_type>
        <parameters>/home/ps/dof_6_ws/src/ur5/config/ur5_control.yaml</parameters>
      </plugin>
      <pose>0 0 0 0 -0 0</pose>
    </model>
    <model name="ur5_bin">
      <link name="bottom">
        <pose>0 0 0 0 -0 0</pose>
        <collision name="collision">
          <geometry>
            <box>
              <size>0.4 0.4 0.02</size>
            </box>
          </geometry>
          <max_contacts>10</max_contacts>
          <surface>
            <contact>
              <ode/>
            </contact>
            <bounce/>
            <friction>
              <torsional>
                <ode/>
              </torsional>
              <ode/>
            </friction>
          </surface>
        </collision>
        <visual name="visual">
          <geometry>
            <box>
              <size>0.4 0.4 0.02</size>
            </box>
          </geometry>
          <material>
            <script>
              <uri>file://media/materials/scripts/gazebo.material</uri>
              <name>Gazebo/Blue</name>
            </script>
          </material>
        </visual>
        <inertial>
          <mass>0.05</mass>
          <inertia>
            <ixx>0.001</ixx>
            <ixy>0</ixy>
            <ixz>0</ixz>
            <iyy>0.001</iyy>
            <iyz>0</iyz>
            <izz>0.001</izz>
          </inertia>
          <pose>0 0 0 0 -0 0</pose>
        </inertial>
        <self_collide>0</self_collide>
        <enable_wind>0</enable_wind>
        <kinematic>0</kinematic>
      </link>
      <link name="left">
        <pose>-0.2 0 0.05 0 -0 0</pose>
        <collision name="collision">
          <geometry>
            <box>
              <size>0.02 0.4 0.2</size>
            </box>
          </geometry>
          <max_contacts>10</max_contacts>
          <surface>
            <contact>
              <ode/>
            </contact>
            <bounce/>
            <friction>
              <torsional>
                <ode/>
              </torsional>
              <ode/>
            </friction>
          </surface>
        </collision>
        <visual name="visual">
          <geometry>
            <box>
              <size>0.02 0.4 0.2</size>
            </box>
          </geometry>
          <material>
            <script>
              <uri>file://media/materials/scripts/gazebo.material</uri>
              <name>Gazebo/Blue</name>
            </script>
          </material>
        </visual>
        <inertial>
          <mass>0.05</mass>
          <inertia>
            <ixx>0.001</ixx>
            <ixy>0</ixy>
            <ixz>0</ixz>
            <iyy>0.001</iyy>
            <iyz>0</iyz>
            <izz>0.001</izz>
          </inertia>
          <pose>0 0 0 0 -0 0</pose>
        </inertial>
        <self_collide>0</self_collide>
        <enable_wind>0</enable_wind>
        <kinematic>0</kinematic>
      </link>
      <link name="right">
        <pose>0.2 0 0.05 0 -0 0</pose>
        <collision name="collision">
          <geometry>
            <box>
              <size>0.02 0.4 0.2</size>
            </box>
          </geometry>
          <max_contacts>10</max_contacts>
          <surface>
            <contact>
              <ode/>
            </contact>
            <bounce/>
            <friction>
              <torsional>
                <ode/>
              </torsional>
              <ode/>
            </friction>
          </surface>
        </collision>
        <visual name="visual">
          <geometry>
            <box>
              <size>0.02 0.4 0.2</size>
            </box>
          </geometry>
          <material>
            <script>
              <uri>file://media/materials/scripts/gazebo.material</uri>
              <name>Gazebo/Blue</name>
            </script>
          </material>
        </visual>
        <inertial>
          <mass>0.05</mass>
          <inertia>
            <ixx>0.001</ixx>
            <ixy>0</ixy>
            <ixz>0</ixz>
            <iyy>0.001</iyy>
            <iyz>0</iyz>
            <izz>0.001</izz>
          </inertia>
          <pose>0 0 0 0 -0 0</pose>
        </inertial>
        <self_collide>0</self_collide>
        <enable_wind>0</enable_wind>
        <kinematic>0</kinematic>
      </link>
      <link name="back">
        <pose>0 0.2 0.05 0 -0 0</pose>
        <collision name="collision">
          <geometry>
            <box>
              <size>0.4 0.02 0.2</size>
            </box>
          </geometry>
          <max_contacts>10</max_contacts>
          <surface>
            <contact>
              <ode/>
            </contact>
            <bounce/>
            <friction>
              <torsional>
                <ode/>
              </torsional>
              <ode/>
            </friction>
          </surface>
        </collision>
        <visual name="visual">
          <geometry>
            <box>
              <size>0.4 0.02 0.2</size>
            </box>
          </geometry>
          <material>
            <script>
              <uri>file://media/materials/scripts/gazebo.material</uri>
              <name>Gazebo/Blue</name>
            </script>
          </material>
        </visual>
        <inertial>
          <mass>0.05</mass>
          <inertia>
            <ixx>0.001</ixx>
            <ixy>0</ixy>
            <ixz>0</ixz>
            <iyy>0.001</iyy>
            <iyz>0</iyz>
            <izz>0.001</izz>
          </inertia>
          <pose>0 0 0 0 -0 0</pose>
        </inertial>
        <self_collide>0</self_collide>
        <enable_wind>0</enable_wind>
        <kinematic>0</kinematic>
      </link>
      <link name="front">
        <pose>0 -0.2 0.05 0 -0 0</pose>
        <collision name="collision">
          <geometry>
            <box>
              <size>0.4 0.02 0.2</size>
            </box>
          </geometry>
          <max_contacts>10</max_contacts>
          <surface>
            <contact>
              <ode/>
            </contact>
            <bounce/>
            <friction>
              <torsional>
                <ode/>
              </torsional>
              <ode/>
            </friction>
          </surface>
        </collision>
        <visual name="visual">
          <geometry>
            <box>
              <size>0.4 0.02 0.2</size>
            </box>
          </geometry>
          <material>
            <script>
              <uri>file://media/materials/scripts/gazebo.material</uri>
              <name>Gazebo/Blue</name>
            </script>
          </material>
        </visual>
        <inertial>
          <mass>0.05</mass>
          <inertia>
            <ixx>0.001</ixx>
            <ixy>0</ixy>
            <ixz>0</ixz>
            <iyy>0.001</iyy>
            <iyz>0</iyz>
            <izz>0.001</izz>
          </inertia>
          <pose>0 0 0 0 -0 0</pose>
        </inertial>
        <self_collide>0</self_collide>
        <enable_wind>0</enable_wind>
        <kinematic>0</kinematic>
      </link>
      <joint name="left_wall" type="fixed">
        <parent>bottom</parent>
        <child>left</child>
      </joint>
      <joint name="right_wall" type="fixed">
        <parent>bottom</parent>
        <child>right</child>
      </joint>
      <joint name="back_wall" type="fixed">
        <parent>bottom</parent>
        <child>back</child>
      </joint>
      <joint name="front_wall" type="fixed">
        <parent>bottom</parent>
        <child>front</child>
      </joint>
      <pose>0.119037 -0.622409 0 0 -0 0</pose>
    </model>
    <model name="box2">
      <link name="body">
        <visual name="visual">
          <pose>0 0 0.015 0 -0 0</pose>
          <geometry>
            <mesh>
              <uri>model://box2/box2.stl</uri>
              <scale>1 1 1</scale>
            </mesh>
          </geometry>
          <material>
            <script>
              <uri>model://box2/materials/scripts</uri>
              <uri>model://box2/materials/textures</uri>
              <name>box2color</name>
            </script>
            <shader type="vertex">
              <normal_map>__default__</normal_map>
            </shader>
            <ambient>1 1 1 1</ambient>
            <diffuse>1 1 1 1</diffuse>
            <specular>0 0 0 1</specular>
            <emissive>0 0 0 1</emissive>
          </material>
        </visual>
        <collision name="collision_0">
          <laser_retro>0</laser_retro>
          <max_contacts>10</max_contacts>
          <pose>-0.005 0 0 0 -0 0</pose>
          <geometry>
            <box>
              <size>0.42 0.21 0.005</size>
            </box>
          </geometry>
          <surface>
            <friction>
              <ode>
                <mu>1</mu>
                <mu2>1</mu2>
                <fdir1>0 0 0</fdir1>
                <slip1>0</slip1>
                <slip2>0</slip2>
              </ode>
              <torsional>
                <coefficient>1</coefficient>
                <patch_radius>0</patch_radius>
                <surface_radius>0</surface_radius>
                <use_patch_radius>1</use_patch_radius>
                <ode>
                  <slip>0</slip>
                </ode>
              </torsional>
            </friction>
            <bounce>
              <restitution_coefficient>0</restitution_coefficient>
              <threshold>1e+06</threshold>
            </bounce>
            <contact>
              <collide_without_contact>0</collide_without_contact>
              <collide_without_contact_bitmask>1</collide_without_contact_bitmask>
              <collide_bitmask>1</collide_bitmask>
              <ode>
                <soft_cfm>0</soft_cfm>
                <soft_erp>0.2</soft_erp>
                <kp>1e+13</kp>
                <kd>1</kd>
                <max_vel>0.01</max_vel>
                <min_depth>0</min_depth>
              </ode>
              <bullet>
                <split_impulse>1</split_impulse>
                <split_impulse_penetration_threshold>-0.01</split_impulse_penetration_threshold>
                <soft_cfm>0</soft_cfm>
                <soft_erp>0.2</soft_erp>
                <kp>1e+13</kp>
                <kd>1</kd>
              </bullet>
            </contact>
          </surface>
        </collision>
        <self_collide>0</self_collide>
        <enable_wind>0</enable_wind>
        <kinematic>0</kinematic>
      </link>
      <static>1</static>
      <pose>-0.435378 -0.55958 0 0 -0 0</pose>
    </model>
    <state world_name="default">
      <sim_time>47 988000000</sim_time>
      <real_time>48 456765478</real_time>
      <wall_time>1729420037 57570415</wall_time>
      <iterations>47988</iterations>
      <model name="box2">
        <pose>0.010954 -0.554747 0.205891 0 -0 0</pose>
        <scale>1 1 1</scale>
        <link name="body">
          <pose>0.010954 -0.554747 0.205891 0 -0 0</pose>
          <velocity>0 0 0 0 -0 0</velocity>
          <acceleration>0 0 0 0 -0 0</acceleration>
          <wrench>0 0 0 0 -0 0</wrench>
        </link>
      </model>
      <model name="box2_1">
        <pose>0.012415 -0.763659 0.205105 0 -0 0</pose>
        <scale>1 1 1</scale>
        <link name="body">
          <pose>0.012415 -0.763659 0.205105 0 -0 0</pose>
          <velocity>0 0 0 0 -0 0</velocity>
          <acceleration>0 0 0 0 -0 0</acceleration>
          <wrench>0 0 0 0 -0 0</wrench>
        </link>
      </model>
      <model name="box2_2">
        <pose>0.512755 -0.763757 0.20573 0 -0 0</pose>
        <scale>1 1 1</scale>
        <link name="body">
          <pose>0.512755 -0.763757 0.20573 0 -0 0</pose>
          <velocity>0 0 0 0 -0 0</velocity>
          <acceleration>0 0 0 0 -0 0</acceleration>
          <wrench>0 0 0 0 -0 0</wrench>
        </link>
      </model>
      <model name="box2_3">
        <pose>0.513035 -0.554483 0.206622 0 -0 0</pose>
        <scale>1 1 1</scale>
        <link name="body">
          <pose>0.513035 -0.554483 0.206622 0 -0 0</pose>
          <velocity>0 0 0 0 -0 0</velocity>
          <acceleration>0 0 0 0 -0 0</acceleration>
          <wrench>0 0 0 0 -0 0</wrench>
        </link>
      </model>
      <model name="conveyor_belt">
        <pose>-0.004468 0.571948 -0.203431 0 0 -1.54483</pose>
        <scale>1 1 1</scale>
        <model name="conveyorbelt_fixed">
          <pose>-0.004468 0.571948 -0.203431 0 0 -1.54483</pose>
          <scale>1 1 1</scale>
          <link name="belt_visual">
            <pose>-0.004468 0.571948 -0.203431 0 0 -1.54483</pose>
            <velocity>0 0 0 0 -0 0</velocity>
            <acceleration>0 0 0 0 -0 0</acceleration>
            <wrench>0 0 0 0 -0 0</wrench>
          </link>
        </model>
        <model name="conveyorbelt_moving">
          <pose>-0.004468 0.571948 0.537569 0 0 -1.54483</pose>
          <scale>1 1 1</scale>
          <link name="belt_moving">
            <pose>-0.004468 0.571948 0.537569 0 0 -1.54483</pose>
            <velocity>0 0 0 0 -0 0</velocity>
            <acceleration>0 0 0 0 -0 0</acceleration>
            <wrench>0 0 0 0 -0 0</wrench>
          </link>
        </model>
      </model>
      <model name="ground_plane">
        <pose>0 0 0 0 -0 0</pose>
        <scale>1 1 1</scale>
        <link name="link">
          <pose>0 0 0 0 -0 0</pose>
          <velocity>0 0 0 0 -0 0</velocity>
          <acceleration>0 0 0 0 -0 0</acceleration>
          <wrench>0 0 0 0 -0 0</wrench>
        </link>
      </model>
      <model name="my_model_1">
        <pose>-0.149691 -0.518378 0.23246 -2e-06 -5.4e-05 8e-06</pose>
        <scale>1 1 1</scale>
        <link name="link">
          <pose>-0.149691 -0.518378 0.23246 -2e-06 -5.4e-05 8e-06</pose>
          <velocity>0 0 0 0 -0 0</velocity>
          <acceleration>0 0 -9.8 0 -0 0</acceleration>
          <wrench>0 0 -9.8 0 -0 0</wrench>
        </link>
      </model>
      <model name="my_model_2">
        <pose>-0.155178 -0.717457 0.231865 0 -1.5e-05 -1.2e-05</pose>
        <scale>1 1 1</scale>
        <link name="link">
          <pose>-0.155178 -0.717457 0.231865 0 -1.5e-05 -1.2e-05</pose>
          <velocity>0 0 0 0 -0 0</velocity>
          <acceleration>-0.07027 -0.07027 -0.397874 -0.330827 -0.330787 3.14159</acceleration>
          <wrench>-0.07027 -0.07027 -0.397874 0 -0 0</wrench>
        </link>
      </model>
      <model name="my_model_3">
        <pose>0.342315 -0.515696 0.233519 1.2e-05 -0.000102 -1.1e-05</pose>
        <scale>1 1 1</scale>
        <link name="link">
          <pose>0.342315 -0.515696 0.233519 1.2e-05 -0.000102 -1.1e-05</pose>
          <velocity>0 0 0 0 -0 0</velocity>
          <acceleration>0.072156 0.072164 -0.144331 0.255042 0.255113 3.14159</acceleration>
          <wrench>0.072156 0.072164 -0.144331 0 -0 0</wrench>
        </link>
      </model>
      <model name="my_model_4">
        <pose>0.341825 -0.719323 0.233998 -4e-06 -3e-06 -3e-06</pose>
        <scale>1 1 1</scale>
        <link name="link">
          <pose>0.341825 -0.719323 0.233998 -4e-06 -3e-06 -3e-06</pose>
          <velocity>0 0 0 0 -0 0</velocity>
          <acceleration>0.072166 -0.072166 -0.144329 -0.255019 0.255031 3.14159</acceleration>
          <wrench>0.072166 -0.072166 -0.144329 0 -0 0</wrench>
        </link>
      </model>
      <model name="ur5_bin">
        <pose>0.005516 -0.673696 0.05 -2e-06 2e-06 -0.004352</pose>
        <scale>1 1 1</scale>
        <link name="back">
          <pose>0.006387 -0.473698 0.1 -2e-06 1e-06 -0.004353</pose>
          <velocity>-0.000113 0.000115 -0.000176 -0.000797 -0.001113 -0.000171</velocity>
          <acceleration>-0.162638 0.171099 -0.276817 1.72405 -1.52908 3.00034</acceleration>
          <wrench>-0.008132 0.008555 -0.013841 0 -0 0</wrench>
        </link>
        <link name="bottom">
          <pose>0.005516 -0.673696 0.05 -2e-06 2e-06 -0.004352</pose>
          <velocity>-8.5e-05 0.000112 -7.5e-05 -0.00063 -0.00043 0.00022</velocity>
          <acceleration>-0.104364 0.144805 -0.084401 -1.21334 -0.916462 0.230517</acceleration>
          <wrench>-0.005218 0.00724 -0.00422 0 -0 0</wrench>
        </link>
        <link name="front">
          <pose>0.004646 -0.873694 0.1 -2e-06 1e-06 -0.004352</pose>
          <velocity>-5.6e-05 0.000129 9e-05 -0.000792 -0.000539 0.000248</velocity>
          <acceleration>-0.107189 0.19629 0.193884 -1.36585 -1.05708 0.296194</acceleration>
          <wrench>-0.005359 0.009815 0.009694 0 -0 0</wrench>
        </link>
        <link name="left">
          <pose>-0.194482 -0.672826 0.1 -2e-06 1e-06 -0.004352</pose>
          <velocity>-0.000112 8.8e-05 -0.000136 -0.000902 -0.00052 0.0003</velocity>
          <acceleration>-0.152119 0.144545 -0.243529 -1.46549 -1.02057 0.249365</acceleration>
          <wrench>-0.007606 0.007227 -0.012176 0 -0 0</wrench>
        </link>
        <link name="right">
          <pose>0.205514 -0.674567 0.1 -1e-06 2e-06 -0.004352</pose>
          <velocity>-0.000104 0.000188 -1.1e-05 7.6e-05 -0.000852 9.4e-05</velocity>
          <acceleration>-0.152942 0.251539 0.078559 -0.562269 -1.3166 0.084418</acceleration>
          <wrench>-0.007647 0.012577 0.003928 0 -0 0</wrench>
        </link>
      </model>
      <model name="ur5_bin_2">
        <pose>0.502543 -0.669034 0.05 0 -0 1.1e-05</pose>
        <scale>1 1 1</scale>
        <link name="back">
          <pose>0.50254 -0.469034 0.1 0 -0 1.1e-05</pose>
          <velocity>3.8e-05 -3.5e-05 1e-06 4.9e-05 -5.8e-05 -9.1e-05</velocity>
          <acceleration>0.087989 2.22281 -9.15547 2.59341 0.445662 -0.088918</acceleration>
          <wrench>0.004399 0.111141 -0.457773 0 -0 0</wrench>
        </link>
        <link name="bottom">
          <pose>0.502543 -0.669034 0.05 0 -0 1.1e-05</pose>
          <velocity>2.8e-05 -4.6e-05 1.5e-05 0.000102 -2.6e-05 -0.000162</velocity>
          <acceleration>0.048529 1.05912 -4.60612 2.5221 0.428967 -0.158416</acceleration>
          <wrench>0.002426 0.052956 -0.230306 0 -0 0</wrench>
        </link>
        <link name="front">
          <pose>0.502545 -0.869034 0.1 2e-06 -0 1.2e-05</pose>
          <velocity>6e-06 -2.4e-05 1.7e-05 0.000212 6.1e-05 -4e-06</velocity>
          <acceleration>0.087536 2.23649 -0.061012 2.75155 0.874774 -0.003085</acceleration>
          <wrench>0.004377 0.111824 -0.003051 0 -0 0</wrench>
        </link>
        <link name="left">
          <pose>0.302543 -0.669036 0.1 1e-06 0 1.1e-05</pose>
          <velocity>2.2e-05 -1.6e-05 7e-06 0.000144 5e-06 -0.000108</velocity>
          <acceleration>0.069238 2.24269 -4.5282 2.69085 0.479265 -0.108031</acceleration>
          <wrench>0.003462 0.112135 -0.22641 0 -0 0</wrench>
        </link>
        <link name="right">
          <pose>0.702543 -0.669032 0.1 0 -0 1.1e-05</pose>
          <velocity>2.5e-05 -9.9e-05 1.8e-05 -2.3e-05 -3e-06 -8.3e-05</velocity>
          <acceleration>0.07757 2.17563 -4.68954 2.36442 0.527383 -0.083105</acceleration>
          <wrench>0.003879 0.108781 -0.234477 0 -0 0</wrench>
        </link>
      </model>
      <light name="sun">
        <pose>0 0 10 0 -0 0</pose>
      </light>
    </state>
    <model name="conveyor_belt">
      <model name="conveyorbelt_fixed">
        <static>1</static>
        <link name="belt_link">
          <visual name="visual">
            <geometry>
              <mesh>
                <scale>1 1 1</scale>
                <uri>model://conveyor_belt/meshes/conveyor_belt.dae</uri>
              </mesh>
            </geometry>
          </visual>
          <collision name="collision">
            <geometry>
              <mesh>
                <scale>1 1 1</scale>
                <uri>model://conveyor_belt/meshes/conveyor_belt.dae</uri>
              </mesh>
            </geometry>
            <max_contacts>10</max_contacts>
            <surface>
              <contact>
                <ode/>
              </contact>
              <bounce/>
              <friction>
                <torsional>
                  <ode/>
                </torsional>
                <ode/>
              </friction>
            </surface>
            <origin xyz="0.0 0.0 0" rpy="0.0 0.0 0.0"/>
          </collision>
          <self_collide>0</self_collide>
          <enable_wind>0</enable_wind>
          <kinematic>0</kinematic>
        </link>
      </model>
      <model name="conveyorbelt_moving">
        <allow_auto_disable>0</allow_auto_disable>
        <static>0</static>
        <pose>0 0 0.741 0 -0 0</pose>
        <link name="belt_moving">
          <inertial>
            <mass>100</mass>
            <inertia>
              <ixx>0</ixx>
              <ixy>0</ixy>
              <ixz>0&lt;/ixx&gt;
          <iyy>0</iyy>
                <iyz>0</iyz>
                <izz>0</izz>
              </ixz>
            </inertia>
            <pose>0 0 0 0 -0 0</pose>
          </inertial>
          <collision name="belt_collision">
            <geometry>
              <box>
                <size>0.425 1.2 1e-05</size>
              </box>
            </geometry>
            <surface>
              <friction>
                <ode>
                  <mu>100</mu>
                  <mu2>100</mu2>
                </ode>
                <torsional>
                  <coefficient>1000</coefficient>
                  <patch_radius>0.1</patch_radius>
                  <ode/>
                </torsional>
              </friction>
              <contact>
                <ode/>
              </contact>
              <bounce/>
            </surface>
            <max_contacts>10</max_contacts>
          </collision>
          <self_collide>0</self_collide>
          <enable_wind>0</enable_wind>
          <kinematic>0</kinematic>
        </link>
      </model><!-- Joint connecting the fixed and moving parts -->
      <joint name="belt_joint" type="prismatic">
        <parent>conveyorbelt_fixed::belt_link</parent>
        <child>conveyorbelt_moving::belt_moving</child>
        <axis>
          <xyz expressed_in="__model__">0 1 0</xyz>
          <limit>
            <lower>0</lower>
            <upper>0.01</upper>
          </limit>
          <dynamics>
            <spring_reference>0</spring_reference>
            <spring_stiffness>0</spring_stiffness>
          </dynamics>
        </axis>
      </joint>
      <link name="proximity_sensor_link">
        <static>1</static>
        <gravity>0</gravity>
        <pose>-0.21 0 0.75 0 0 0</pose>
        <visual name="proximity_sensor_visual">
          <geometry>
            <box>
              <size>0.05 0.01 0.02</size>
            </box>
          </geometry>
          <material>
            <ambient>1 0 0 1</ambient>
            <diffuse>1 0 0 1</diffuse>
          </material>
        </visual>
        <sensor name="proximity_sensor" type="ray">
          <pose>0 0 0.01 0 0 0</pose>
          <ray>
            <scan>
              <horizontal>
                <samples>1</samples>
                <resolution>1</resolution>
                <min_angle>0</min_angle>
                <max_angle>0</max_angle>
              </horizontal>
            </scan>
            <range>
              <min>0.01</min>
              <max>0.4</max>
            </range>
          </ray>
          <plugin name="proximity_sensor_plugin" filename="libgazebo_ros_ray_sensor.so">
            <ros>
              <namespace>proximity_sensor</namespace>
              <remapping>~/out:=/prox</remapping>
            </ros>
            <output_type>sensor_msgs/LaserScan</output_type>
            <update_rate>30</update_rate>
          </plugin>
          <visualize>true</visualize>
        </sensor>
      </link><!-- Plugin for the conveyor belt -->
      <plugin name="ros2_conveyorbelt_plugin" filename="libros2_conveyorbelt_plugin.so">
        <ros>
          <namespace/>
        </ros>
        <max_velocity>1.0</max_velocity>
        <publish_rate>1000</publish_rate>
      </plugin>
      <pose>-0.004468 0.571948 -0.203431 0 -0 -1.54483</pose>
      <gazebo>
        <plugin filename="libROS2ConveyorBeltPlugin.so" name="ros2_conveyorbelt_plugin">
          <ros>
            <namespace/>
          </ros>
          <max_velocity>0.2</max_velocity>
          <publish_rate>10</publish_rate>
        </plugin>
      </gazebo>
    </model>
    <model name="my_model_1">
      <pose>-0.323261 -0.41637 0 0 -0 0</pose>
      <static>0</static>
      <link name="link">
        <inertial>
          <mass>1</mass>
          <inertia>
            <ixx>0.083</ixx>
            <ixy>0</ixy>
            <ixz>0</ixz>
            <iyy>0.083</iyy>
            <iyz>0</iyz>
            <izz>0.083</izz>
          </inertia>
          <pose>0 0 0 0 -0 0</pose>
        </inertial>
        <collision name="collision">
          <geometry>
            <box>
              <size>0.05 0.05 0.05</size>
            </box>
          </geometry>
          <max_contacts>10</max_contacts>
          <surface>
            <contact>
              <ode/>
            </contact>
            <bounce/>
            <friction>
              <torsional>
                <ode/>
              </torsional>
              <ode/>
            </friction>
          </surface>
        </collision>
        <visual name="visual">
          <geometry>
            <box>
              <size>0.05 0.05 0.05</size>
            </box>
          </geometry>
          <material>
            <ambient>1 1 1 1</ambient>
            <diffuse>1 1 1 1</diffuse>
            <specular>0 0 0 1</specular>
            <emissive>0 0 0 1</emissive>
          </material>
        </visual>
        <visual name="aruco_mark">
          <pose>0 0 0.0252 0 -0 1.5708</pose>
          <cast_shadows>0</cast_shadows>
          <geometry>
            <box>
              <size>0.05 0.05 1e-06</size>
            </box>
          </geometry>
          <material>
            <script>
              <uri>model://the_cube/materials/scripts</uri>
              <uri>model://the_cube/materials/textures/</uri>
              <name>aruco_mark_0/Image</name>
            </script>
          </material>
        </visual>
        <self_collide>0</self_collide>
        <enable_wind>0</enable_wind>
        <kinematic>0</kinematic>
      </link>
    </model>
    <model name="my_model_2">
      <pose>-0.461978 -0.424841 0 0 -0 0</pose>
      <static>0</static>
      <link name="link">
        <inertial>
          <mass>1</mass>
          <inertia>
            <ixx>0.083</ixx>
            <ixy>0</ixy>
            <ixz>0</ixz>
            <iyy>0.083</iyy>
            <iyz>0</iyz>
            <izz>0.083</izz>
          </inertia>
          <pose>0 0 0 0 -0 0</pose>
        </inertial>
        <collision name="collision">
          <geometry>
            <box>
              <size>0.05 0.05 0.05</size>
            </box>
          </geometry>
          <max_contacts>10</max_contacts>
          <surface>
            <contact>
              <ode/>
            </contact>
            <bounce/>
            <friction>
              <torsional>
                <ode/>
              </torsional>
              <ode/>
            </friction>
          </surface>
        </collision>
        <visual name="visual">
          <geometry>
            <box>
              <size>0.05 0.05 0.05</size>
            </box>
          </geometry>
          <material>
            <ambient>1 1 1 1</ambient>
            <diffuse>1 1 1 1</diffuse>
            <specular>0 0 0 1</specular>
            <emissive>0 0 0 1</emissive>
          </material>
        </visual>
        <visual name="aruco_mark1">
          <pose>0 0 0.0252 0 -0 1.5708</pose>
          <cast_shadows>0</cast_shadows>
          <geometry>
            <box>
              <size>0.05 0.05 1e-06</size>
            </box>
          </geometry>
          <material>
            <script>
              <uri>model://the_cube_1/materials/scripts</uri>
              <uri>model://the_cube_1/materials/textures/</uri>
              <name>aruco_mark_1/Image</name>
            </script>
          </material>
        </visual>
        <self_collide>0</self_collide>
        <enable_wind>0</enable_wind>
        <kinematic>0</kinematic>
      </link>
    </model>
    <model name="my_model_3">
      <pose>-0.578378 -0.440835 0 0 -0 0</pose>
      <static>0</static>
      <link name="link">
        <inertial>
          <mass>1</mass>
          <inertia>
            <ixx>0.083</ixx>
            <ixy>0</ixy>
            <ixz>0</ixz>
            <iyy>0.083</iyy>
            <iyz>0</iyz>
            <izz>0.083</izz>
          </inertia>
          <pose>0 0 0 0 -0 0</pose>
        </inertial>
        <collision name="collision">
          <geometry>
            <box>
              <size>0.05 0.05 0.05</size>
            </box>
          </geometry>
          <max_contacts>10</max_contacts>
          <surface>
            <contact>
              <ode/>
            </contact>
            <bounce/>
            <friction>
              <torsional>
                <ode/>
              </torsional>
              <ode/>
            </friction>
          </surface>
        </collision>
        <visual name="visual">
          <geometry>
            <box>
              <size>0.05 0.05 0.05</size>
            </box>
          </geometry>
          <material>
            <ambient>1 1 1 1</ambient>
            <diffuse>1 1 1 1</diffuse>
            <specular>0 0 0 1</specular>
            <emissive>0 0 0 1</emissive>
          </material>
        </visual>
        <visual name="aruco_mark1">
          <pose>0 0 0.0252 0 -0 1.5708</pose>
          <cast_shadows>0</cast_shadows>
          <geometry>
            <box>
              <size>0.05 0.05 1e-06</size>
            </box>
          </geometry>
          <material>
            <script>
              <uri>model://the_cube_2/materials/scripts</uri>
              <uri>model://the_cube_2/materials/textures/</uri>
              <name>aruco_mark_2/Image</name>
            </script>
          </material>
        </visual>
        <self_collide>0</self_collide>
        <enable_wind>0</enable_wind>
        <kinematic>0</kinematic>
      </link>
    </model>
    <model name="my_model_4">
      <pose>-0.572291 -0.563974 0 0 -0 0</pose>
      <static>0</static>
      <link name="link">
        <inertial>
          <mass>1</mass>
          <inertia>
            <ixx>0.083</ixx>
            <ixy>0</ixy>
            <ixz>0</ixz>
            <iyy>0.083</iyy>
            <iyz>0</iyz>
            <izz>0.083</izz>
          </inertia>
          <pose>0 0 0 0 -0 0</pose>
        </inertial>
        <collision name="collision">
          <geometry>
            <box>
              <size>0.05 0.05 0.05</size>
            </box>
          </geometry>
          <max_contacts>10</max_contacts>
          <surface>
            <contact>
              <ode/>
            </contact>
            <bounce/>
            <friction>
              <torsional>
                <ode/>
              </torsional>
              <ode/>
            </friction>
          </surface>
        </collision>
        <visual name="visual">
          <geometry>
            <box>
              <size>0.05 0.05 0.05</size>
            </box>
          </geometry>
          <material>
            <ambient>1 1 1 1</ambient>
            <diffuse>1 1 1 1</diffuse>
            <specular>0 0 0 1</specular>
            <emissive>0 0 0 1</emissive>
          </material>
        </visual>
        <visual name="aruco_mark1">
          <pose>0 0 0.0252 0 -0 1.5708</pose>
          <cast_shadows>0</cast_shadows>
          <geometry>
            <box>
              <size>0.05 0.05 1e-06</size>
            </box>
          </geometry>
          <material>
            <script>
              <uri>model://the_cube_3/materials/scripts</uri>
              <uri>model://the_cube_3/materials/textures/</uri>
              <name>aruco_mark_5/Image</name>
            </script>
          </material>
        </visual>
        <self_collide>0</self_collide>
        <enable_wind>0</enable_wind>
        <kinematic>0</kinematic>
      </link>
    </model>
    <model name="ur5_bin_2">
      <link name="bottom">
        <pose>0 0 0 0 -0 0</pose>
        <collision name="collision">
          <geometry>
            <box>
              <size>0.4 0.4 0.02</size>
            </box>
          </geometry>
          <max_contacts>10</max_contacts>
          <surface>
            <contact>
              <ode/>
            </contact>
            <bounce/>
            <friction>
              <torsional>
                <ode/>
              </torsional>
              <ode/>
            </friction>
          </surface>
        </collision>
        <visual name="visual">
          <geometry>
            <box>
              <size>0.4 0.4 0.02</size>
            </box>
          </geometry>
          <material>
            <script>
              <uri>file://media/materials/scripts/gazebo.material</uri>
              <name>Gazebo/Orange</name>
            </script>
          </material>
        </visual>
        <inertial>
          <mass>0.05</mass>
          <inertia>
            <ixx>0.001</ixx>
            <ixy>0</ixy>
            <ixz>0</ixz>
            <iyy>0.001</iyy>
            <iyz>0</iyz>
            <izz>0.001</izz>
          </inertia>
          <pose>0 0 0 0 -0 0</pose>
        </inertial>
        <self_collide>0</self_collide>
        <enable_wind>0</enable_wind>
        <kinematic>0</kinematic>
      </link>
      <link name="left">
        <pose>-0.2 0 0.05 0 -0 0</pose>
        <collision name="collision">
          <geometry>
            <box>
              <size>0.02 0.4 0.2</size>
            </box>
          </geometry>
          <max_contacts>10</max_contacts>
          <surface>
            <contact>
              <ode/>
            </contact>
            <bounce/>
            <friction>
              <torsional>
                <ode/>
              </torsional>
              <ode/>
            </friction>
          </surface>
        </collision>
        <visual name="visual">
          <geometry>
            <box>
              <size>0.02 0.4 0.2</size>
            </box>
          </geometry>
          <material>
            <script>
              <uri>file://media/materials/scripts/gazebo.material</uri>
              <name>Gazebo/Orange</name>
            </script>
          </material>
        </visual>
        <inertial>
          <mass>0.05</mass>
          <inertia>
            <ixx>0.001</ixx>
            <ixy>0</ixy>
            <ixz>0</ixz>
            <iyy>0.001</iyy>
            <iyz>0</iyz>
            <izz>0.001</izz>
          </inertia>
          <pose>0 0 0 0 -0 0</pose>
        </inertial>
        <self_collide>0</self_collide>
        <enable_wind>0</enable_wind>
        <kinematic>0</kinematic>
      </link>
      <link name="right">
        <pose>0.2 0 0.05 0 -0 0</pose>
        <collision name="collision">
          <geometry>
            <box>
              <size>0.02 0.4 0.2</size>
            </box>
          </geometry>
          <max_contacts>10</max_contacts>
          <surface>
            <contact>
              <ode/>
            </contact>
            <bounce/>
            <friction>
              <torsional>
                <ode/>
              </torsional>
              <ode/>
            </friction>
          </surface>
        </collision>
        <visual name="visual">
          <geometry>
            <box>
              <size>0.02 0.4 0.2</size>
            </box>
          </geometry>
          <material>
            <script>
              <uri>file://media/materials/scripts/gazebo.material</uri>
              <name>Gazebo/Orange</name>
            </script>
          </material>
        </visual>
        <inertial>
          <mass>0.05</mass>
          <inertia>
            <ixx>0.001</ixx>
            <ixy>0</ixy>
            <ixz>0</ixz>
            <iyy>0.001</iyy>
            <iyz>0</iyz>
            <izz>0.001</izz>
          </inertia>
          <pose>0 0 0 0 -0 0</pose>
        </inertial>
        <self_collide>0</self_collide>
        <enable_wind>0</enable_wind>
        <kinematic>0</kinematic>
      </link>
      <link name="back">
        <pose>0 0.2 0.05 0 -0 0</pose>
        <collision name="collision">
          <geometry>
            <box>
              <size>0.4 0.02 0.2</size>
            </box>
          </geometry>
          <max_contacts>10</max_contacts>
          <surface>
            <contact>
              <ode/>
            </contact>
            <bounce/>
            <friction>
              <torsional>
                <ode/>
              </torsional>
              <ode/>
            </friction>
          </surface>
        </collision>
        <visual name="visual">
          <geometry>
            <box>
              <size>0.4 0.02 0.2</size>
            </box>
          </geometry>
          <material>
            <script>
              <uri>file://media/materials/scripts/gazebo.material</uri>
              <name>Gazebo/Orange</name>
            </script>
          </material>
        </visual>
        <inertial>
          <mass>0.05</mass>
          <inertia>
            <ixx>0.001</ixx>
            <ixy>0</ixy>
            <ixz>0</ixz>
            <iyy>0.001</iyy>
            <iyz>0</iyz>
            <izz>0.001</izz>
          </inertia>
          <pose>0 0 0 0 -0 0</pose>
        </inertial>
        <self_collide>0</self_collide>
        <enable_wind>0</enable_wind>
        <kinematic>0</kinematic>
      </link>
      <link name="front">
        <pose>0 -0.2 0.05 0 -0 0</pose>
        <collision name="collision">
          <geometry>
            <box>
              <size>0.4 0.02 0.2</size>
            </box>
          </geometry>
          <max_contacts>10</max_contacts>
          <surface>
            <contact>
              <ode/>
            </contact>
            <bounce/>
            <friction>
              <torsional>
                <ode/>
              </torsional>
              <ode/>
            </friction>
          </surface>
        </collision>
        <visual name="visual">
          <geometry>
            <box>
              <size>0.4 0.02 0.2</size>
            </box>
          </geometry>
          <material>
            <script>
              <uri>file://media/materials/scripts/gazebo.material</uri>
              <name>Gazebo/Orange</name>
            </script>
          </material>
        </visual>
        <inertial>
          <mass>0.05</mass>
          <inertia>
            <ixx>0.001</ixx>
            <ixy>0</ixy>
            <ixz>0</ixz>
            <iyy>0.001</iyy>
            <iyz>0</iyz>
            <izz>0.001</izz>
          </inertia>
          <pose>0 0 0 0 -0 0</pose>
        </inertial>
        <self_collide>0</self_collide>
        <enable_wind>0</enable_wind>
        <kinematic>0</kinematic>
      </link>
      <joint name="left_wall" type="fixed">
        <parent>bottom</parent>
        <child>left</child>
      </joint>
      <joint name="right_wall" type="fixed">
        <parent>bottom</parent>
        <child>right</child>
      </joint>
      <joint name="back_wall" type="fixed">
        <parent>bottom</parent>
        <child>back</child>
      </joint>
      <joint name="front_wall" type="fixed">
        <parent>bottom</parent>
        <child>front</child>
      </joint>
      <pose>0.502535 -0.663127 0 0 -0 0</pose>
    </model>
    <model name="box2_1">
      <link name="body">
        <visual name="visual">
          <pose>0 0 0.015 0 -0 0</pose>
          <geometry>
            <mesh>
              <uri>model://box2_1/box2.stl</uri>
              <scale>1 1 1</scale>
            </mesh>
          </geometry>
          <material>
            <script>
              <uri>model://box2_1/materials/scripts</uri>
              <uri>model://box2_1/materials/textures</uri>
              <name>box2color</name>
            </script>
            <shader type="vertex">
              <normal_map>__default__</normal_map>
            </shader>
            <ambient>1 1 1 1</ambient>
            <diffuse>1 1 1 1</diffuse>
            <specular>0 0 0 1</specular>
            <emissive>0 0 0 1</emissive>
          </material>
        </visual>
        <collision name="collision_0">
          <laser_retro>0</laser_retro>
          <max_contacts>10</max_contacts>
          <pose>-0.005 0 0 0 -0 0</pose>
          <geometry>
            <box>
              <size>0.42 0.21 0.005</size>
            </box>
          </geometry>
          <surface>
            <friction>
              <ode>
                <mu>1</mu>
                <mu2>1</mu2>
                <fdir1>0 0 0</fdir1>
                <slip1>0</slip1>
                <slip2>0</slip2>
              </ode>
              <torsional>
                <coefficient>1</coefficient>
                <patch_radius>0</patch_radius>
                <surface_radius>0</surface_radius>
                <use_patch_radius>1</use_patch_radius>
                <ode>
                  <slip>0</slip>
                </ode>
              </torsional>
            </friction>
            <bounce>
              <restitution_coefficient>0</restitution_coefficient>
              <threshold>1e+06</threshold>
            </bounce>
            <contact>
              <collide_without_contact>0</collide_without_contact>
              <collide_without_contact_bitmask>1</collide_without_contact_bitmask>
              <collide_bitmask>1</collide_bitmask>
              <ode>
                <soft_cfm>0</soft_cfm>
                <soft_erp>0.2</soft_erp>
                <kp>1e+13</kp>
                <kd>1</kd>
                <max_vel>0.01</max_vel>
                <min_depth>0</min_depth>
              </ode>
              <bullet>
                <split_impulse>1</split_impulse>
                <split_impulse_penetration_threshold>-0.01</split_impulse_penetration_threshold>
                <soft_cfm>0</soft_cfm>
                <soft_erp>0.2</soft_erp>
                <kp>1e+13</kp>
                <kd>1</kd>
              </bullet>
            </contact>
          </surface>
        </collision>
        <self_collide>0</self_collide>
        <enable_wind>0</enable_wind>
        <kinematic>0</kinematic>
      </link>
      <static>1</static>
      <pose>0.013993 -1.04754 0 0 -0 0</pose>
    </model>
    <model name="box2_2">
      <link name="body">
        <visual name="visual">
          <pose>0 0 0.015 0 -0 0</pose>
          <geometry>
            <mesh>
              <uri>model://box2_2/box2.stl</uri>
              <scale>1 1 1</scale>
            </mesh>
          </geometry>
          <material>
            <script>
              <uri>model://box2_2/materials/scripts</uri>
              <uri>model://box2_2/materials/textures</uri>
              <name>box2color</name>
            </script>
            <shader type="vertex">
              <normal_map>__default__</normal_map>
            </shader>
            <ambient>1 1 1 1</ambient>
            <diffuse>1 1 1 1</diffuse>
            <specular>0 0 0 1</specular>
            <emissive>0 0 0 1</emissive>
          </material>
        </visual>
        <collision name="collision_0">
          <laser_retro>0</laser_retro>
          <max_contacts>10</max_contacts>
          <pose>-0.005 0 0 0 -0 0</pose>
          <geometry>
            <box>
              <size>0.42 0.21 0.005</size>
            </box>
          </geometry>
          <surface>
            <friction>
              <ode>
                <mu>1</mu>
                <mu2>1</mu2>
                <fdir1>0 0 0</fdir1>
                <slip1>0</slip1>
                <slip2>0</slip2>
              </ode>
              <torsional>
                <coefficient>1</coefficient>
                <patch_radius>0</patch_radius>
                <surface_radius>0</surface_radius>
                <use_patch_radius>1</use_patch_radius>
                <ode>
                  <slip>0</slip>
                </ode>
              </torsional>
            </friction>
            <bounce>
              <restitution_coefficient>0</restitution_coefficient>
              <threshold>1e+06</threshold>
            </bounce>
            <contact>
              <collide_without_contact>0</collide_without_contact>
              <collide_without_contact_bitmask>1</collide_without_contact_bitmask>
              <collide_bitmask>1</collide_bitmask>
              <ode>
                <soft_cfm>0</soft_cfm>
                <soft_erp>0.2</soft_erp>
                <kp>1e+13</kp>
                <kd>1</kd>
                <max_vel>0.01</max_vel>
                <min_depth>0</min_depth>
              </ode>
              <bullet>
                <split_impulse>1</split_impulse>
                <split_impulse_penetration_threshold>-0.01</split_impulse_penetration_threshold>
                <soft_cfm>0</soft_cfm>
                <soft_erp>0.2</soft_erp>
                <kp>1e+13</kp>
                <kd>1</kd>
              </bullet>
            </contact>
          </surface>
        </collision>
        <self_collide>0</self_collide>
        <enable_wind>0</enable_wind>
        <kinematic>0</kinematic>
      </link>
      <static>1</static>
      <pose>0.515198 -1.0257 0 0 -0 0</pose>
    </model>
    <model name="box2_3">
      <link name="body">
        <visual name="visual">
          <pose>0 0 0.015 0 -0 0</pose>
          <geometry>
            <mesh>
              <uri>model://box2_3/box2.stl</uri>
              <scale>1 1 1</scale>
            </mesh>
          </geometry>
          <material>
            <script>
              <uri>model://box2_3/materials/scripts</uri>
              <uri>model://box2_3/materials/textures</uri>
              <name>box2color</name>
            </script>
            <shader type="vertex">
              <normal_map>__default__</normal_map>
            </shader>
            <ambient>1 1 1 1</ambient>
            <diffuse>1 1 1 1</diffuse>
            <specular>0 0 0 1</specular>
            <emissive>0 0 0 1</emissive>
          </material>
        </visual>
        <collision name="collision_0">
          <laser_retro>0</laser_retro>
          <max_contacts>10</max_contacts>
          <pose>-0.005 0 0 0 -0 0</pose>
          <geometry>
            <box>
              <size>0.42 0.21 0.005</size>
            </box>
          </geometry>
          <surface>
            <friction>
              <ode>
                <mu>1</mu>
                <mu2>1</mu2>
                <fdir1>0 0 0</fdir1>
                <slip1>0</slip1>
                <slip2>0</slip2>
              </ode>
              <torsional>
                <coefficient>1</coefficient>
                <patch_radius>0</patch_radius>
                <surface_radius>0</surface_radius>
                <use_patch_radius>1</use_patch_radius>
                <ode>
                  <slip>0</slip>
                </ode>
              </torsional>
            </friction>
            <bounce>
              <restitution_coefficient>0</restitution_coefficient>
              <threshold>1e+06</threshold>
            </bounce>
            <contact>
              <collide_without_contact>0</collide_without_contact>
              <collide_without_contact_bitmask>1</collide_without_contact_bitmask>
              <collide_bitmask>1</collide_bitmask>
              <ode>
                <soft_cfm>0</soft_cfm>
                <soft_erp>0.2</soft_erp>
                <kp>1e+13</kp>
                <kd>1</kd>
                <max_vel>0.01</max_vel>
                <min_depth>0</min_depth>
              </ode>
              <bullet>
                <split_impulse>1</split_impulse>
                <split_impulse_penetration_threshold>-0.01</split_impulse_penetration_threshold>
                <soft_cfm>0</soft_cfm>
                <soft_erp>0.2</soft_erp>
                <kp>1e+13</kp>
                <kd>1</kd>
              </bullet>
            </contact>
          </surface>
        </collision>
        <self_collide>0</self_collide>
        <enable_wind>0</enable_wind>
        <kinematic>0</kinematic>
      </link>
      <static>1</static>
      <pose>0.547992 -0.18346 0 0 -0 0</pose>
    </model>
  </world>
</sdf>