<sdf version='1.7'>
  <world name='default'>
    <light name='sun' type='directional'>
      <cast_shadows>1</cast_shadows>
      <pose>0 0 10 0 -0 0</pose>
      <diffuse>0.8 0.8 0.8 1</diffuse>
      <specular>0.2 0.2 0.2 1</specular>
      <attenuation>
        <range>1000</range>
        <constant>0.9</constant>
        <linear>0.01</linear>
        <quadratic>0.001</quadratic>
      </attenuation>
      <direction>-0.5 0.1 -0.9</direction>
      <spot>
        <inner_angle>0</inner_angle>
        <outer_angle>0</outer_angle>
        <falloff>0</falloff>
      </spot>
    </light>
    <model name='ground_plane'>
      <static>1</static>
      <link name='link'>
        <collision name='collision'>
          <geometry>
            <plane>
              <normal>0 0 1</normal>
              <size>100 100</size>
            </plane>
          </geometry>
          <surface>
            <friction>
              <ode>
                <mu>100</mu>
                <mu2>50</mu2>
              </ode>
              <torsional>
                <ode/>
              </torsional>
            </friction>
            <contact>
              <ode/>
            </contact>
            <bounce/>
          </surface>
          <max_contacts>10</max_contacts>
        </collision>
        <visual name='visual'>
          <cast_shadows>0</cast_shadows>
          <geometry>
            <plane>
              <normal>0 0 1</normal>
              <size>100 100</size>
            </plane>
          </geometry>
          <material>
            <script>
              <uri>file://media/materials/scripts/gazebo.material</uri>
              <name>Gazebo/Grey</name>
            </script>
          </material>
        </visual>
        <self_collide>0</self_collide>
        <enable_wind>0</enable_wind>
        <kinematic>0</kinematic>
      </link>
    </model>
    <gravity>0 0 -9.8</gravity>
    <magnetic_field>6e-06 2.3e-05 -4.2e-05</magnetic_field>
    <atmosphere type='adiabatic'/>
    <physics type='ode'>
      <max_step_size>0.001</max_step_size>
      <real_time_factor>1</real_time_factor>
      <real_time_update_rate>1000</real_time_update_rate>
    </physics>
    <scene>
      <ambient>0.4 0.4 0.4 1</ambient>
      <background>0.7 0.7 0.7 1</background>
      <shadows>1</shadows>
    </scene>
    <audio>
      <device>default</device>
    </audio>
    <wind/>
    <spherical_coordinates>
      <surface_model>EARTH_WGS84</surface_model>
      <latitude_deg>0</latitude_deg>
      <longitude_deg>0</longitude_deg>
      <elevation>0</elevation>
      <heading_deg>0</heading_deg>
    </spherical_coordinates>
     <model name='ur5'>
      <joint name='world_to_base' type='fixed'>
        <pose relative_to='__model__'>0 0 0 0 -0 0</pose>
        <parent>world</parent>
        <child>base_link</child>
      </joint>
      <link name='base_link'>
        <pose relative_to='world_to_base'>0 0 0 0 -0 0</pose>
        <inertial>
          <pose>-0.000367 -0.000368 0.016561 0 -0 0</pose>
          <mass>4</mass>
          <inertia>
            <ixx>0.00060258</ixx>
            <ixy>1.7502e-05</ixy>
            <ixz>1.5277e-06</ixz>
            <iyy>0.00060261</iyy>
            <iyz>1.5241e-06</iyz>
            <izz>0.0010709</izz>
          </inertia>
        </inertial>
        <collision name='base_link_collision'>
          <pose>0 0 0 0 -0 0</pose>
          <geometry>
            <mesh>
              <scale>1 1 1</scale>
              <uri>/home/ps/dof_6_ws/src/ur5/meshes/base_link.STL</uri>
            </mesh>
          </geometry>
          <surface>
            <contact>
              <ode/>
            </contact>
            <friction>
              <ode/>
              <torsional>
                <ode/>
              </torsional>
            </friction>
            <bounce/>
          </surface>
          <max_contacts>10</max_contacts>
        </collision>
        <visual name='base_link_visual'>
          <pose>0 0 0 0 -0 0</pose>
          <geometry>
            <mesh>
              <scale>1 1 1</scale>
              <uri>/home/ps/dof_6_ws/src/ur5/meshes/base_link.STL</uri>
            </mesh>
          </geometry>
          <material>
            <script>
              <name>Gazebo/Yellow</name>
              <uri>file://media/materials/scripts/gazebo.material</uri>
            </script>
          </material>
        </visual>
        <self_collide>0</self_collide>
        <enable_wind>0</enable_wind>
        <kinematic>0</kinematic>
      </link>
      <joint name='shoulder_pan_joint' type='revolute'>
        <pose relative_to='base_link'>0 0 0.009992 -1.57079 1.57079 3.14159</pose>
        <parent>base_link</parent>
        <child>shoulder_link</child>
        <axis>
          <xyz>1 0 0</xyz>
          <limit>
            <lower>-6.2832</lower>
            <upper>6.2832</upper>
            <effort>300</effort>
            <velocity>3</velocity>
          </limit>
          <dynamics>
            <damping>10</damping>
            <friction>1</friction>
            <spring_reference>0</spring_reference>
            <spring_stiffness>0</spring_stiffness>
          </dynamics>
        </axis>
      </joint>
      <link name='shoulder_link'>
        <pose relative_to='shoulder_pan_joint'>0 0 0 0 -0 0</pose>
        <inertial>
          <pose>-0.078966 0.016439 -6e-06 0 -0 0</pose>
          <mass>3.7</mass>
          <inertia>
            <ixx>0.0028298</ixx>
            <ixy>0.00031932</ixy>
            <ixz>-1.3132e-07</ixz>
            <iyy>0.002538</iyy>
            <iyz>4.4907e-07</iyz>
            <izz>0.0026207</izz>
          </inertia>
        </inertial>
        <collision name='shoulder_link_collision'>
          <pose>0 0 0 0 -0 0</pose>
          <geometry>
            <mesh>
              <scale>1 1 1</scale>
              <uri>/home/ps/dof_6_ws/src/ur5/meshes/shoulder_link.STL</uri>
            </mesh>
          </geometry>
          <surface>
            <contact>
              <ode/>
            </contact>
            <friction>
              <ode/>
              <torsional>
                <ode/>
              </torsional>
            </friction>
            <bounce/>
          </surface>
          <max_contacts>10</max_contacts>
        </collision>
        <visual name='shoulder_link_visual'>
          <pose>0 0 0 0 -0 0</pose>
          <geometry>
            <mesh>
              <scale>1 1 1</scale>
              <uri>/home/ps/dof_6_ws/src/ur5/meshes/shoulder_link.STL</uri>
            </mesh>
          </geometry>
          <material>
            <script>
              <name>Gazebo/Yellow</name>
              <uri>file://media/materials/scripts/gazebo.material</uri>
            </script>
          </material>
        </visual>
        <self_collide>1</self_collide>
        <enable_wind>0</enable_wind>
        <kinematic>0</kinematic>
      </link>
      <joint name='shoulder_lift_joint' type='revolute'>
        <pose relative_to='shoulder_link'>-0.080008 0.053821 0 0 -0 0</pose>
        <parent>shoulder_link</parent>
        <child>upper_arm_link</child>
        <axis>
          <xyz>0 -1 0</xyz>
          <limit>
            <lower>-6.2832</lower>
            <upper>6.2832</upper>
            <effort>200</effort>
            <velocity>3</velocity>
          </limit>
          <dynamics>
            <damping>10</damping>
            <friction>1</friction>
            <spring_reference>0</spring_reference>
            <spring_stiffness>0</spring_stiffness>
          </dynamics>
        </axis>
      </joint>
      <link name='upper_arm_link'>
        <pose relative_to='shoulder_lift_joint'>0 0 0 0 -0 0</pose>
        <inertial>
          <pose>-0.21652 0.079293 0 0 -0 0</pose>
          <mass>8.393</mass>
          <inertia>
            <ixx>0.0063671</ixx>
            <ixy>-9.2154e-12</ixy>
            <ixz>9.0018e-07</ixz>
            <iyy>0.021824</iyy>
            <iyz>-2.2572e-07</iyz>
            <izz>0.021327</izz>
          </inertia>
        </inertial>
        <collision name='upper_arm_link_collision'>
          <pose>0 0 0 0 -0 0</pose>
          <geometry>
            <mesh>
              <scale>1 1 1</scale>
              <uri>/home/ps/dof_6_ws/src/ur5/meshes/upper_arm_link.STL</uri>
            </mesh>
          </geometry>
          <surface>
            <contact>
              <ode/>
            </contact>
            <friction>
              <ode/>
              <torsional>
                <ode/>
              </torsional>
            </friction>
            <bounce/>
          </surface>
          <max_contacts>10</max_contacts>
        </collision>
        <visual name='upper_arm_link_visual'>
          <pose>0 0 0 0 -0 0</pose>
          <geometry>
            <mesh>
              <scale>1 1 1</scale>
              <uri>/home/ps/dof_6_ws/src/ur5/meshes/upper_arm_link.STL</uri>
            </mesh>
          </geometry>
          <material>
            <script>
              <name>Gazebo/White</name>
              <uri>file://media/materials/scripts/gazebo.material</uri>
            </script>
          </material>
        </visual>
        <self_collide>1</self_collide>
        <enable_wind>0</enable_wind>
        <kinematic>0</kinematic>
      </link>
      <joint name='elbow_joint' type='revolute'>
        <pose relative_to='upper_arm_link'>-0.425 0 0 0 -0 0</pose>
        <parent>upper_arm_link</parent>
        <child>forearm_link</child>
        <axis>
          <xyz>0 1 0</xyz>
          <limit>
            <lower>-6.2832</lower>
            <upper>6.2832</upper>
            <effort>200</effort>
            <velocity>3</velocity>
          </limit>
          <dynamics>
            <damping>10</damping>
            <friction>1</friction>
            <spring_reference>0</spring_reference>
            <spring_stiffness>0</spring_stiffness>
          </dynamics>
        </axis>
      </joint>
      <link name='forearm_link'>
        <pose relative_to='elbow_joint'>0 0 0 0 -0 0</pose>
        <inertial>
          <pose>-0.1739 -0.033049 -3e-06 0 -0 0</pose>
          <mass>2.275</mass>
          <inertia>
            <ixx>0.002241</ixx>
            <ixy>-0.00011285</ixy>
            <ixz>4.2229e-07</ixz>
            <iyy>0.011808</iyy>
            <iyz>-2.6928e-07</iyz>
            <izz>0.011655</izz>
          </inertia>
        </inertial>
        <collision name='forearm_link_collision'>
          <pose>0 0 0 0 -0 0</pose>
          <geometry>
            <mesh>
              <scale>1 1 1</scale>
              <uri>/home/ps/dof_6_ws/src/ur5/meshes/forearm_link.STL</uri>
            </mesh>
          </geometry>
          <surface>
            <contact>
              <ode/>
            </contact>
            <friction>
              <ode/>
              <torsional>
                <ode/>
              </torsional>
            </friction>
            <bounce/>
          </surface>
          <max_contacts>10</max_contacts>
        </collision>
        <visual name='forearm_link_visual'>
          <pose>0 0 0 0 -0 0</pose>
          <geometry>
            <mesh>
              <scale>1 1 1</scale>
              <uri>/home/ps/dof_6_ws/src/ur5/meshes/forearm_link.STL</uri>
            </mesh>
          </geometry>
          <material>
            <script>
              <name>Gazebo/White</name>
              <uri>file://media/materials/scripts/gazebo.material</uri>
            </script>
          </material>
        </visual>
        <self_collide>1</self_collide>
        <enable_wind>0</enable_wind>
        <kinematic>0</kinematic>
      </link>
      <joint name='wrist_1_joint' type='revolute'>
        <pose relative_to='forearm_link'>-0.39225 0 0 0 -0 0</pose>
        <parent>forearm_link</parent>
        <child>wrist_1_link</child>
        <axis>
          <xyz>0 -1 0</xyz>
          <limit>
            <lower>-6.2832</lower>
            <upper>6.2832</upper>
            <effort>200</effort>
            <velocity>3</velocity>
          </limit>
          <dynamics>
            <damping>10</damping>
            <friction>1</friction>
            <spring_reference>0</spring_reference>
            <spring_stiffness>0</spring_stiffness>
          </dynamics>
        </axis>
      </joint>
      <link name='wrist_1_link'>
        <pose relative_to='wrist_1_joint'>0 0 0 0 -0 0</pose>
        <inertial>
          <pose>0.003753 0.044978 1.3e-05 0 -0 0</pose>
          <mass>1.219</mass>
          <inertia>
            <ixx>0.00041141</ixx>
            <ixy>4.2784e-05</ixy>
            <ixz>-2.8598e-07</ixz>
            <iyy>0.00036744</iyy>
            <iyz>4.089e-07</iyz>
            <izz>0.000387</izz>
          </inertia>
        </inertial>
        <collision name='wrist_1_link_collision'>
          <pose>0 0 0 0 -0 0</pose>
          <geometry>
            <mesh>
              <scale>1 1 1</scale>
              <uri>/home/ps/dof_6_ws/src/ur5/meshes/wrist_1_link.STL</uri>
            </mesh>
          </geometry>
          <surface>
            <contact>
              <ode/>
            </contact>
            <friction>
              <ode/>
              <torsional>
                <ode/>
              </torsional>
            </friction>
            <bounce/>
          </surface>
          <max_contacts>10</max_contacts>
        </collision>
        <visual name='wrist_1_link_visual'>
          <pose>0 0 0 0 -0 0</pose>
          <geometry>
            <mesh>
              <scale>1 1 1</scale>
              <uri>/home/ps/dof_6_ws/src/ur5/meshes/wrist_1_link.STL</uri>
            </mesh>
          </geometry>
          <material>
            <script>
              <name>Gazebo/White</name>
              <uri>file://media/materials/scripts/gazebo.material</uri>
            </script>
          </material>
        </visual>
        <self_collide>1</self_collide>
        <enable_wind>0</enable_wind>
        <kinematic>0</kinematic>
      </link>
      <joint name='wrist_2_joint' type='revolute'>
        <pose relative_to='wrist_1_link'>0 0.056149 0 0 -0 0</pose>
        <parent>wrist_1_link</parent>
        <child>wrist_2_link</child>
        <axis>
          <xyz>1 0 0</xyz>
          <limit>
            <lower>-6.2832</lower>
            <upper>6.2832</upper>
            <effort>200</effort>
            <velocity>3</velocity>
          </limit>
          <dynamics>
            <damping>10</damping>
            <friction>1</friction>
            <spring_reference>0</spring_reference>
            <spring_stiffness>0</spring_stiffness>
          </dynamics>
        </axis>
      </joint>
      <link name='wrist_2_link'>
        <pose relative_to='wrist_2_joint'>0 0 0 0 -0 0</pose>
        <inertial>
          <pose>-0.083749 -0.003753 -1.2e-05 0 -0 0</pose>
          <mass>1.219</mass>
          <inertia>
            <ixx>0.00036744</ixx>
            <ixy>4.2782e-05</ixy>
            <ixz>4.1013e-07</ixz>
            <iyy>0.0004114</iyy>
            <iyz>-2.8709e-07</iyz>
            <izz>0.000387</izz>
          </inertia>
        </inertial>
        <collision name='wrist_2_link_collision'>
          <pose>0 0 0 0 -0 0</pose>
          <geometry>
            <mesh>
              <scale>1 1 1</scale>
              <uri>/home/ps/dof_6_ws/src/ur5/meshes/wrist_2_link.STL</uri>
            </mesh>
          </geometry>
          <surface>
            <contact>
              <ode/>
            </contact>
            <friction>
              <ode/>
              <torsional>
                <ode/>
              </torsional>
            </friction>
            <bounce/>
          </surface>
          <max_contacts>10</max_contacts>
        </collision>
        <visual name='wrist_2_link_visual'>
          <pose>0 0 0 0 -0 0</pose>
          <geometry>
            <mesh>
              <scale>1 1 1</scale>
              <uri>/home/ps/dof_6_ws/src/ur5/meshes/wrist_2_link.STL</uri>
            </mesh>
          </geometry>
          <material>
            <script>
              <name>Gazebo/White</name>
              <uri>file://media/materials/scripts/gazebo.material</uri>
            </script>
          </material>
        </visual>
        <self_collide>1</self_collide>
        <enable_wind>0</enable_wind>
        <kinematic>0</kinematic>
      </link>
      <joint name='wrist_3_joint' type='revolute'>
        <pose relative_to='wrist_2_link'>-0.09492 0.041547 0 -3.14159 -0 -3.14159</pose>
        <parent>wrist_2_link</parent>
        <child>wrist_3_link</child>
        <axis>
          <xyz>0 -1 0</xyz>
          <limit>
            <lower>-6.2832</lower>
            <upper>6.2832</upper>
            <effort>200</effort>
            <velocity>3</velocity>
          </limit>
          <dynamics>
            <damping>10</damping>
            <friction>1</friction>
            <spring_reference>0</spring_reference>
            <spring_stiffness>0</spring_stiffness>
          </dynamics>
        </axis>
      </joint>
      <link name='wrist_3_link'>
        <pose relative_to='wrist_3_joint'>0 0 0 0 -0 0</pose>
        <inertial>
          <pose>-7.6e-05 0.018179 0.00012 0 -0 0</pose>
          <mass>0.18791</mass>
          <inertia>
            <ixx>6.9269e-05</ixx>
            <ixy>5.70242e-08</ixy>
            <ixz>-3.20042e-07</ixz>
            <iyy>0.000117056</iyy>
            <iyz>-8.83978e-08</iyz>
            <izz>6.95671e-05</izz>
          </inertia>
        </inertial>
        <collision name='wrist_3_link_collision'>
          <pose>0 0 0 0 -0 0</pose>
          <geometry>
            <mesh>
              <scale>1 1 1</scale>
              <uri>/home/ps/dof_6_ws/src/ur5/meshes/wrist_3_link.STL</uri>
            </mesh>
          </geometry>
          <surface>
            <contact>
              <ode/>
            </contact>
            <friction>
              <ode/>
              <mu>100</mu>   
              <mu2>100</mu2> 
                <ode/>
            </friction>
            <bounce/>
          </surface>
          <max_contacts>10</max_contacts>
        </collision>
        <collision name='wrist_3_link_fixed_joint_lump__camera_link_collision_1'>
          <pose>0.03 0.04 0 0 0 1.508</pose>
          <geometry>
            <box>
              <size>0.01 0.01 0.01</size>
            </box>
          </geometry>
          <surface>
            <contact>
              <ode/>
            </contact>
            <friction>
              <ode/>
              <torsional>
                <ode/>
              </torsional>
            </friction>
            <bounce/>
          </surface>
          <max_contacts>10</max_contacts>
        </collision>
        <visual name='wrist_3_link_visual'>
          <pose>0 0 0 0 -0 0</pose>
          <geometry>
            <mesh>
              <scale>1 1 1</scale>
              <uri>/home/ps/dof_6_ws/src/ur5/meshes/wrist_3_link.STL</uri>
            </mesh>
          </geometry>
          <material>
            <script>
              <name>Gazebo/Red</name>
              <uri>file://media/materials/scripts/gazebo.material</uri>
            </script>
          </material>
        </visual>
        <visual name='wrist_3_link_fixed_joint_lump__camera_link_visual_1'>
          <pose>0.03 0.04 0 0 0 1.508</pose>
          <geometry>
            <box>
              <size>0.01 0.01 0.01</size>
            </box>
          </geometry>
          <material>
            <script>
              <name>Gazebo/Black</name>
              <uri>file://media/materials/scripts/gazebo.material</uri>
            </script>
          </material>
        </visual>
        <self_collide>1</self_collide>
        <sensor name='camera1' type='camera'>
          <update_rate>30</update_rate>
          <camera name='head'>
            <horizontal_fov>1.39626</horizontal_fov>
            <image>
              <width>640</width>
              <height>480</height>
              <format>R8G8B8</format>
            </image>
            <clip>
              <near>0.02</near>
              <far>300</far>
            </clip>
            <noise>
              <type>gaussian</type>
              <mean>0</mean>
              <stddev>0.007</stddev>
            </noise>
          </camera>
          <plugin name='camera_controller' filename='libgazebo_ros_camera.so'>
            <alwaysOn>1</alwaysOn>
            <updateRate>0.0</updateRate>
            <cameraName>ur5/usbcam</cameraName>
            <imageTopicName>image_raw</imageTopicName>
            <cameraInfoTopicName>camera_info</cameraInfoTopicName>
            <frameName>camera_link_optical</frameName>
            <hackBaseline>0.0</hackBaseline>
            <distortionK1>0.0</distortionK1>
            <distortionK2>0.0</distortionK2>
            <distortionK3>0.0</distortionK3>
            <distortionT1>0.0</distortionT1>
            <distortionT2>0.0</distortionT2>
            <CxPrime>0</CxPrime>
            <Cx>0.0</Cx>
            <Cy>0.0</Cy>
            <focalLength>0.0</focalLength>
          </plugin>
          <pose>0.03 0.04 0 0 0 1.508</pose>
        </sensor>
        <enable_wind>0</enable_wind>
        <kinematic>0</kinematic>
      </link>
      <joint name='gripper_joint1' type='revolute'>
        <pose relative_to='wrist_3_link'>0 0.04 0 1.57 -0 0</pose>
        <parent>wrist_3_link</parent>
        <child>vacuum_gripper1</child>
        <axis>
          <xyz>1 0 0</xyz>
          <limit>
            <lower>0</lower>
            <upper>0</upper>
            <effort>50</effort>
            <velocity>10</velocity>
          </limit>
          <dynamics>
            <damping>0</damping>
            <friction>1000</friction>
            <spring_reference>0</spring_reference>
            <spring_stiffness>0</spring_stiffness>
          </dynamics>
        </axis>
      </joint>
      <link name='vacuum_gripper1'>
        <pose relative_to='gripper_joint1'>0 0 0 0 -0 0</pose>
        <inertial>
          <pose>0 0 0 0 -0 0</pose>
          <mass>0.0001</mass>
          <inertia>
            <ixx>1e-08</ixx>
            <ixy>0</ixy>
            <ixz>0</ixz>
            <iyy>1e-08</iyy>
            <iyz>0</iyz>
            <izz>1e-08</izz>
          </inertia>
        </inertial>
        <visual name='vacuum_gripper1_visual'>
          <pose>0 0 0 0 -0 0</pose>
          <geometry>
            <cylinder>
              <length>0.015</length>
              <radius>0.02</radius>
            </cylinder>
          </geometry>
          <material>
            <script>
              <name>Gazebo/Black</name>
              <uri>file://media/materials/scripts/gazebo.material</uri>
            </script>
          </material>
        </visual>
        <self_collide>0</self_collide>
        <enable_wind>0</enable_wind>
        <kinematic>0</kinematic>
      </link>
      <plugin name='gazebo_ros_vacuum_gripper1' filename='libgazebo_ros_vacuum_gripper.so'>
        <robotNamespace>/ur5/vacuum_gripper1</robotNamespace>
        <link_name>vacuum_gripper1</link_name>
        <bodyName>vacuum_gripper1</bodyName>
        <topicName>grasping1</topicName>
        <maxForce>1000000000</maxForce>
        <maxDistance>0.05</maxDistance>
        <minDistance>0.01</minDistance>
      </plugin>
      <static>0</static>
      <plugin name='gazebo_ros2_control' filename='libgazebo_ros2_control.so'>
        <robot_sim_type>gazebo_ros2_control/GazeboSystem</robot_sim_type>
        <parameters>/home/ps/dof_6_ws/src/ur5/config/ur5_control.yaml</parameters>
      </plugin>
      <pose>0 0 0 0 -0 0</pose>
    </model>
    <model name='ur5_bin'>
      <link name='bottom'>
        <pose>0 0 0 0 -0 0</pose>
        <collision name='collision'>
          <geometry>
            <box>
              <size>0.4 0.4 0.02</size>
            </box>
          </geometry>
          <max_contacts>10</max_contacts>
          <surface>
            <contact>
              <ode/>
            </contact>
            <bounce/>
            <friction>
              <torsional>
                <ode/>
              </torsional>
              <ode/>
            </friction>
          </surface>
        </collision>
        <visual name='visual'>
          <geometry>
            <box>
              <size>0.4 0.4 0.02</size>
            </box>
          </geometry>
          <material>
            <script>
              <uri>file://media/materials/scripts/gazebo.material</uri>
              <name>Gazebo/Blue</name>
            </script>
          </material>
        </visual>
        <inertial>
          <mass>0.05</mass>
          <inertia>
            <ixx>0.001</ixx>
            <ixy>0</ixy>
            <ixz>0</ixz>
            <iyy>0.001</iyy>
            <iyz>0</iyz>
            <izz>0.001</izz>
          </inertia>
          <pose>0 0 0 0 -0 0</pose>
        </inertial>
        <self_collide>0</self_collide>
        <enable_wind>0</enable_wind>
        <kinematic>0</kinematic>
      </link>
      <link name='left'>
        <pose>-0.2 0 0.05 0 -0 0</pose>
        <collision name='collision'>
          <geometry>
            <box>
              <size>0.02 0.4 0.2</size>
            </box>
          </geometry>
          <max_contacts>10</max_contacts>
          <surface>
            <contact>
              <ode/>
            </contact>
            <bounce/>
            <friction>
              <torsional>
                <ode/>
              </torsional>
              <ode/>
            </friction>
          </surface>
        </collision>
        <visual name='visual'>
          <geometry>
            <box>
              <size>0.02 0.4 0.2</size>
            </box>
          </geometry>
          <material>
            <script>
              <uri>file://media/materials/scripts/gazebo.material</uri>
              <name>Gazebo/Blue</name>
            </script>
          </material>
        </visual>
        <inertial>
          <mass>0.05</mass>
          <inertia>
            <ixx>0.001</ixx>
            <ixy>0</ixy>
            <ixz>0</ixz>
            <iyy>0.001</iyy>
            <iyz>0</iyz>
            <izz>0.001</izz>
          </inertia>
          <pose>0 0 0 0 -0 0</pose>
        </inertial>
        <self_collide>0</self_collide>
        <enable_wind>0</enable_wind>
        <kinematic>0</kinematic>
      </link>
      <link name='right'>
        <pose>0.2 0 0.05 0 -0 0</pose>
        <collision name='collision'>
          <geometry>
            <box>
              <size>0.02 0.4 0.2</size>
            </box>
          </geometry>
          <max_contacts>10</max_contacts>
          <surface>
            <contact>
              <ode/>
            </contact>
            <bounce/>
            <friction>
              <torsional>
                <ode/>
              </torsional>
              <ode/>
            </friction>
          </surface>
        </collision>
        <visual name='visual'>
          <geometry>
            <box>
              <size>0.02 0.4 0.2</size>
            </box>
          </geometry>
          <material>
            <script>
              <uri>file://media/materials/scripts/gazebo.material</uri>
              <name>Gazebo/Blue</name>
            </script>
          </material>
        </visual>
        <inertial>
          <mass>0.05</mass>
          <inertia>
            <ixx>0.001</ixx>
            <ixy>0</ixy>
            <ixz>0</ixz>
            <iyy>0.001</iyy>
            <iyz>0</iyz>
            <izz>0.001</izz>
          </inertia>
          <pose>0 0 0 0 -0 0</pose>
        </inertial>
        <self_collide>0</self_collide>
        <enable_wind>0</enable_wind>
        <kinematic>0</kinematic>
      </link>
      <link name='back'>
        <pose>0 0.2 0.05 0 -0 0</pose>
        <collision name='collision'>
          <geometry>
            <box>
              <size>0.4 0.02 0.2</size>
            </box>
          </geometry>
          <max_contacts>10</max_contacts>
          <surface>
            <contact>
              <ode/>
            </contact>
            <bounce/>
            <friction>
              <torsional>
                <ode/>
              </torsional>
              <ode/>
            </friction>
          </surface>
        </collision>
        <visual name='visual'>
          <geometry>
            <box>
              <size>0.4 0.02 0.2</size>
            </box>
          </geometry>
          <material>
            <script>
              <uri>file://media/materials/scripts/gazebo.material</uri>
              <name>Gazebo/Blue</name>
            </script>
          </material>
        </visual>
        <inertial>
          <mass>0.05</mass>
          <inertia>
            <ixx>0.001</ixx>
            <ixy>0</ixy>
            <ixz>0</ixz>
            <iyy>0.001</iyy>
            <iyz>0</iyz>
            <izz>0.001</izz>
          </inertia>
          <pose>0 0 0 0 -0 0</pose>
        </inertial>
        <self_collide>0</self_collide>
        <enable_wind>0</enable_wind>
        <kinematic>0</kinematic>
      </link>
      <link name='front'>
        <pose>0 -0.2 0.05 0 -0 0</pose>
        <collision name='collision'>
          <geometry>
            <box>
              <size>0.4 0.02 0.2</size>
            </box>
          </geometry>
          <max_contacts>10</max_contacts>
          <surface>
            <contact>
              <ode/>
            </contact>
            <bounce/>
            <friction>
              <torsional>
                <ode/>
              </torsional>
              <ode/>
            </friction>
          </surface>
        </collision>
        <visual name='visual'>
          <geometry>
            <box>
              <size>0.4 0.02 0.2</size>
            </box>
          </geometry>
          <material>
            <script>
              <uri>file://media/materials/scripts/gazebo.material</uri>
              <name>Gazebo/Blue</name>
            </script>
          </material>
        </visual>
        <inertial>
          <mass>0.05</mass>
          <inertia>
            <ixx>0.001</ixx>
            <ixy>0</ixy>
            <ixz>0</ixz>
            <iyy>0.001</iyy>
            <iyz>0</iyz>
            <izz>0.001</izz>
          </inertia>
          <pose>0 0 0 0 -0 0</pose>
        </inertial>
        <self_collide>0</self_collide>
        <enable_wind>0</enable_wind>
        <kinematic>0</kinematic>
      </link>
      <joint name='left_wall' type='fixed'>
        <parent>bottom</parent>
        <child>left</child>
      </joint>
      <joint name='right_wall' type='fixed'>
        <parent>bottom</parent>
        <child>right</child>
      </joint>
      <joint name='back_wall' type='fixed'>
        <parent>bottom</parent>
        <child>back</child>
      </joint>
      <joint name='front_wall' type='fixed'>
        <parent>bottom</parent>
        <child>front</child>
      </joint>
      <pose>0.119037 -0.622409 0 0 -0 0</pose>
    </model>
    <model name='box2'>
      <link name='body'>
        <visual name='visual'>
          <pose>0 0 0.015 0 -0 0</pose>
          <geometry>
            <mesh>
              <uri>model://box2/box2.stl</uri>
              <scale>1 1 1</scale>
            </mesh>
          </geometry>
          <material>
            <script>
              <uri>model://box2/materials/scripts</uri>
              <uri>model://box2/materials/textures</uri>
              <name>box2color</name>
            </script>
            <shader type='vertex'>
              <normal_map>__default__</normal_map>
            </shader>
            <ambient>1 1 1 1</ambient>
            <diffuse>1 1 1 1</diffuse>
            <specular>0 0 0 1</specular>
            <emissive>0 0 0 1</emissive>
          </material>
        </visual>
        <collision name='collision_0'>
          <laser_retro>0</laser_retro>
          <max_contacts>10</max_contacts>
          <pose>-0.005 0 0 0 -0 0</pose>
          <geometry>
            <box>
              <size>0.42 0.21 0.005</size>
            </box>
          </geometry>
          <surface>
            <friction>
              <ode>
                <mu>1</mu>
                <mu2>1</mu2>
                <fdir1>0 0 0</fdir1>
                <slip1>0</slip1>
                <slip2>0</slip2>
              </ode>
              <torsional>
                <coefficient>1</coefficient>
                <patch_radius>0</patch_radius>
                <surface_radius>0</surface_radius>
                <use_patch_radius>1</use_patch_radius>
                <ode>
                  <slip>0</slip>
                </ode>
              </torsional>
            </friction>
            <bounce>
              <restitution_coefficient>0</restitution_coefficient>
              <threshold>1e+06</threshold>
            </bounce>
            <contact>
              <collide_without_contact>0</collide_without_contact>
              <collide_without_contact_bitmask>1</collide_without_contact_bitmask>
              <collide_bitmask>1</collide_bitmask>
              <ode>
                <soft_cfm>0</soft_cfm>
                <soft_erp>0.2</soft_erp>
                <kp>1e+13</kp>
                <kd>1</kd>
                <max_vel>0.01</max_vel>
                <min_depth>0</min_depth>
              </ode>
              <bullet>
                <split_impulse>1</split_impulse>
                <split_impulse_penetration_threshold>-0.01</split_impulse_penetration_threshold>
                <soft_cfm>0</soft_cfm>
                <soft_erp>0.2</soft_erp>
                <kp>1e+13</kp>
                <kd>1</kd>
              </bullet>
            </contact>
          </surface>
        </collision>
        <self_collide>0</self_collide>
        <enable_wind>0</enable_wind>
        <kinematic>0</kinematic>
      </link>
      <static>1</static>
      <pose>-0.435378 -0.55958 0 0 -0 0</pose>
    </model>
    <model name='my_model'>
      <pose>0.15015 -0.274832 0 0 -0 0</pose>
      <static>0</static>
      <link name='link'>
        <inertial>
          <mass>1</mass>
          <inertia>
            <ixx>0.083</ixx>
            <ixy>0</ixy>
            <ixz>0</ixz>
            <iyy>0.083</iyy>
            <iyz>0</iyz>
            <izz>0.083</izz>
          </inertia>
          <pose>0 0 0 0 -0 0</pose>
        </inertial>
        <collision name='collision'>
          <geometry>
            <box>
              <size>0.05 0.05 0.05</size>
            </box>
          </geometry>
          <max_contacts>10</max_contacts>
          <surface>
            <contact>
              <ode/>
            </contact>
            <bounce/>
            <friction>
              <torsional>
                <ode/>
              </torsional>
              <ode/>
            </friction>
          </surface>
        </collision>
        <visual name='visual'>
          <geometry>
            <box>
              <size>0.05 0.05 0.05</size>
            </box>
          </geometry>
          <material>
            <ambient>1 0 0 1</ambient>
            <diffuse>1 0 0 1</diffuse>
            <specular>0 0 0 1</specular>
            <emissive>0 0 0 1</emissive>
          </material>
        </visual>
        <visual name='aruco200'>
          <pose>0 0 0.0252 0 -0 1.5708</pose>
          <cast_shadows>0</cast_shadows>
          <geometry>
            <box>
              <size>0.05 0.05 1e-06</size>
            </box>
          </geometry>
          <material>
            <script>
              <uri>model://cube200/materials/scripts</uri>
              <uri>model://cube200/materials/textures/</uri>
              <name>aruco200/Image</name>
            </script>
          </material>
        </visual>
        <self_collide>0</self_collide>
        <enable_wind>0</enable_wind>
        <kinematic>0</kinematic>
      </link>
    </model>
    <model name='my_model_0'>
      <pose>-0.12815 -0.358578 0 0 -0 0</pose>
      <static>0</static>
      <link name='link'>
        <inertial>
          <mass>1</mass>
          <inertia>
            <ixx>0.083</ixx>
            <ixy>0</ixy>
            <ixz>0</ixz>
            <iyy>0.083</iyy>
            <iyz>0</iyz>
            <izz>0.083</izz>
          </inertia>
          <pose>0 0 0 0 -0 0</pose>
        </inertial>
        <collision name='collision'>
          <geometry>
            <box>
              <size>0.05 0.05 0.05</size>
            </box>
          </geometry>
          <max_contacts>10</max_contacts>
          <surface>
            <contact>
              <ode/>
            </contact>
            <bounce/>
            <friction>
              <torsional>
                <ode/>
              </torsional>
              <ode/>
            </friction>
          </surface>
        </collision>
        <visual name='visual'>
          <geometry>
            <box>
              <size>0.05 0.05 0.05</size>
            </box>
          </geometry>
          <material>
            <ambient>0 1 0 1</ambient>
            <diffuse>0 1 0 1</diffuse>
            <specular>0 0 0 1</specular>
            <emissive>0 0 0 1</emissive>
          </material>
        </visual>
        <visual name='aruco201'>
          <pose>0 0 0.0252 0 -0 1.5708</pose>
          <cast_shadows>0</cast_shadows>
          <geometry>
            <box>
              <size>0.05 0.05 1e-06</size>
            </box>
          </geometry>
          <material>
            <script>
              <uri>model://cube201/materials/scripts</uri>
              <uri>model://cube201/materials/textures/</uri>
              <name>aruco201/Image</name>
            </script>
          </material>
        </visual>
        <self_collide>0</self_collide>
        <enable_wind>0</enable_wind>
        <kinematic>0</kinematic>
      </link>
    </model>
    <state world_name='default'>
      <sim_time>0 0</sim_time>
      <real_time>0 0</real_time>
      <wall_time>1729236879 350374887</wall_time>
      <iterations>0</iterations>
      <model name='box2'>
        <pose>0.009641 -0.55958 0.210526 0 -0 0</pose>
        <scale>1 1 1</scale>
        <link name='body'>
          <pose>0.009641 -0.55958 0.210526 0 -0 0</pose>
          <velocity>0 0 0 0 -0 0</velocity>
          <acceleration>0 0 0 0 -0 0</acceleration>
          <wrench>0 0 0 0 -0 0</wrench>
        </link>
      </model>
      <model name='ground_plane'>
        <pose>0 0 0 0 -0 0</pose>
        <scale>1 1 1</scale>
        <link name='link'>
          <pose>0 0 0 0 -0 0</pose>
          <velocity>0 0 0 0 -0 0</velocity>
          <acceleration>0 0 0 0 -0 0</acceleration>
          <wrench>0 0 0 0 -0 0</wrench>
        </link>
      </model>
      <model name='my_model'>
        <pose>-0.164576 -0.613733 0.238026 -1e-05 -9e-06 0.010082</pose>
        <scale>1 1 1</scale>
        <link name='link'>
          <pose>-0.164576 -0.613733 0.238026 -1e-05 -9e-06 0.010082</pose>
          <velocity>0 0 0 0 -0 0</velocity>
          <acceleration>0.070898 -0.069482 -0.408159 -0.362342 0.305739 3.14159</acceleration>
          <wrench>0.070898 -0.069482 -0.408159 0 -0 0</wrench>
        </link>
      </model>
      <model name='my_model_0'>
        <pose>-0.167729 -0.534325 0.238027 -3.1e-05 2.3e-05 0.002372</pose>
        <scale>1 1 1</scale>
        <link name='link'>
          <pose>-0.167729 -0.534325 0.238027 -3.1e-05 2.3e-05 0.002372</pose>
          <velocity>0 0 0 0 -0 0</velocity>
          <acceleration>-0.071995 -0.072337 -0.144322 -0.248247 -0.261912 3.14159</acceleration>
          <wrench>-0.071995 -0.072337 -0.144322 0 -0 0</wrench>
        </link>
      </model>
      <model name='my_model_1'>
        <pose>-0.000334 0.559978 0.56156 2e-06 -1e-06 4.9e-05</pose>
        <scale>1 1 1</scale>
        <link name='link'>
          <pose>-0.000334 0.559978 0.56156 2e-06 -1e-06 4.9e-05</pose>
          <velocity>0 0 0 0 -0 0</velocity>
          <acceleration>0 0 -9.8 0 -0 0</acceleration>
          <wrench>0 0 -9.8 0 -0 0</wrench>
        </link>
      </model>
      <model name='ur5_bin'>
        <pose>0.005611 -0.672074 0.049996 2.2e-05 1e-06 -0.01447</pose>
        <scale>1 1 1</scale>
        <link name='back'>
          <pose>0.008504 -0.472096 0.1 2.1e-05 -1e-06 -0.01447</pose>
          <velocity>-0.00023 -0.00223 0.000654 0.022443 -0.002305 4.5e-05</velocity>
          <acceleration>-0.20952 -2.30941 0.937467 1.7617 0.463654 3.03011</acceleration>
          <wrench>-0.010476 -0.11547 0.046873 0 -0 0</wrench>
        </link>
        <link name='bottom'>
          <pose>0.005611 -0.672074 0.049996 2.2e-05 1e-06 -0.01447</pose>
          <velocity>-5.2e-05 -0.000836 -0.004222 0.023773 -0.000962 0.000367</velocity>
          <acceleration>-0.016866 -0.853258 -4.22003 3.02182 -0.855811 -2.78172</acceleration>
          <wrench>-0.000843 -0.042663 -0.211001 0 -0 0</wrench>
        </link>
        <link name='front'>
          <pose>0.002717 -0.872054 0.099991 2.3e-05 1e-06 -0.014469</pose>
          <velocity>-0.000236 -0.002105 -0.008959 0.023596 -0.001017 -0.000243</velocity>
          <acceleration>-0.345019 -2.19358 -9.21744 2.82615 -1.0239 2.737</acceleration>
          <wrench>-0.017251 -0.109679 -0.460872 0 -0 0</wrench>
        </link>
        <link name='left'>
          <pose>-0.194368 -0.669181 0.099996 2.2e-05 -0 -0.01447</pose>
          <velocity>-0.000101 -0.002091 -0.004353 0.023776 -0.000867 0.000433</velocity>
          <acceleration>-0.155868 -2.20334 -4.61447 2.90665 -1.13298 -2.42342</acceleration>
          <wrench>-0.007793 -0.110167 -0.230723 0 -0 0</wrench>
        </link>
        <link name='right'>
          <pose>0.20559 -0.674969 0.099996 2.2e-05 1e-06 -0.014469</pose>
          <velocity>-4.3e-05 -0.001904 -0.004164 0.023585 -0.001196 0.000385</velocity>
          <acceleration>-0.075308 -2.04677 -3.90093 2.99659 -0.722631 -2.91498</acceleration>
          <wrench>-0.003765 -0.102339 -0.195047 0 -0 0</wrench>
        </link>
      </model>
      <light name='sun'>
        <pose>0 0 10 0 -0 0</pose>
      </light>
    </state>
    <include>
      <name>conveyor_belt</name>
      <pose>-0.004468 0.571948 -0.203431 0 -0 -1.54483</pose>
      <uri>model://conveyor_belt</uri>
    </include>
  </world>
</sdf>