<?xml version="1.0" ?>

<!--

# ===================================== COPYRIGHT ===================================== #
#                                                                                       #
#  IFRA (Intelligent Flexible Robotics and Assembly) Group, CRANFIELD UNIVERSITY        #
#  Created on behalf of the IFRA Group at Cranfield University, United Kingdom          #
#  E-mail: IFRA@cranfield.ac.uk                                                         #
#                                                                                       #
#  Licensed under the Apache-2.0 License.                                               #
#  You may not use this file except in compliance with the License.                     #
#  You may obtain a copy of the License at: http://www.apache.org/licenses/LICENSE-2.0  #
#                                                                                       #
#  Unless required by applicable law or agreed to in writing, software distributed      #
#  under the License is distributed on an "as-is" basis, without warranties or          #
#  conditions of any kind, either express or implied. See the License for the specific  #
#  language governing permissions and limitations under the License.                    #
#                                                                                       #
#  IFRA Group - Cranfield University                                                    #
#  AUTHORS: Mikel Bueno Viso - Mikel.Bueno-Viso@cranfield.ac.uk                         #
#           Dr. Seemal Asif  - s.asif@cranfield.ac.uk                                   #
#           Prof. Phil Webb  - p.f.webb@cranfield.ac.uk                                 #
#                                                                                       #
#  Date: June, 2023.                                                                    #
#                                                                                       #
# ===================================== COPYRIGHT ===================================== #

# ===================================== COPYRIGHT ===================================== #
#                                                                                       #
#  The CAD file of the ConveyorBelt has been taken from the rokokoo/conveyor_demo ROS2  #
#  package. The .urdf file has been converted to a Gazebo model (.srdf).                #                                                                  
#                                                                                       #
#  Copyright (C) 2021, GitHub/rokokoo                                                   #                                    
#                                                                                       #
# ===================================== COPYRIGHT ===================================== #

# ======= CITE OUR WORK ======= #
# You can cite our work with the following statement:
# IFRA-Cranfield (2023) Gazebo-ROS2 Conveyor Belt Plugin. URL: https://github.com/IFRA-Cranfield/IFRA_ConveyorBelt.

-->

<sdf version="1.4">

    <model name='conveyor_belt'>
        <model name='conveyorbelt_fixed'>
          <static>1</static>
          <link name='belt_visual'>
            <visual name='visual'>
              <geometry>
                <mesh>
                  <scale>1 1 1</scale>
                  <uri>model://conveyor_belt/meshes/conveyor_belt.dae</uri>
                </mesh>
              </geometry>
            </visual>
            <collision name='collision'>
              <geometry>
                <mesh>
                  <scale>1 1 1</scale>
                  <uri>model://conveyor_belt/meshes/conveyor_belt.dae</uri>
                </mesh>
              </geometry>
              <max_contacts>10</max_contacts>
              <surface>
                <contact>
                  <ode/>
                </contact>
                <bounce/>
                <friction>
                  <torsional>
                    <ode/>
                  </torsional>
                  <ode/>
                </friction>
              </surface>
              <origin xyz='0.0 0.0 0' rpy='0.0 0.0 0.0'/>
            </collision>
            <self_collide>0</self_collide>
            <enable_wind>0</enable_wind>
            <kinematic>0</kinematic>
          </link>
        </model>
        <model name='conveyorbelt_moving'>
          <allow_auto_disable>0</allow_auto_disable>
          <static>0</static>
          <pose>0 0 0.741 0 -0 0</pose>
          <link name='belt_moving'>
            <inertial>
              <mass>100</mass>
              <inertia>
                <ixx>0</ixx>
                <ixy>0</ixy>
                <ixz>0</ixz>
                <iyy>0</iyy>
                <iyz>0</iyz>
                <izz>0</izz>
              </inertia>
              <pose>0 0 0 0 -0 0</pose>
            </inertial>
            <collision name='belt_collision'>
              <geometry>
                <box>
                  <size>0.425 1.2 1e-05</size>
                </box>
              </geometry>
              <surface>
                <friction>
                  <ode>
                    <mu>100</mu>
                    <mu2>100</mu2>
                  </ode>
                  <torsional>
                    <coefficient>1000</coefficient>
                    <patch_radius>0.1</patch_radius>
                    <ode/>
                  </torsional>
                </friction>
                <contact>
                  <ode/>
                </contact>
                <bounce/>
              </surface>
              <max_contacts>10</max_contacts>
            </collision>
            <self_collide>0</self_collide>
            <enable_wind>0</enable_wind>
            <kinematic>0</kinematic>
          </link>
        </model>
        <joint name='belt_joint' type='prismatic'>
          <parent>conveyorbelt_fixed::belt_visual</parent>
          <child>conveyorbelt_moving::belt_moving</child>
          <axis>
            <xyz expressed_in='__model__'>0 1 0</xyz>
            <limit>
              <lower>0</lower>
              <upper>0.01</upper>
            </limit>
            <dynamics>
              <spring_reference>0</spring_reference>
              <spring_stiffness>0</spring_stiffness>
            </dynamics>
          </axis>
        </joint>
        <plugin name='ros2_conveyorbelt_plugin' filename='libros2_conveyorbelt_plugin.so'>
          <ros>
            <namespace/>
          </ros>
          <max_velocity>1.0</max_velocity>
          <publish_rate>1000</publish_rate>
        </plugin>
        <pose>0.657691 -0.081448 0 0 -0 0</pose>
        <gazebo>
          <plugin filename='libROS2ConveyorBeltPlugin.so' name='ros2_conveyorbelt_plugin'>
            <ros>
              <namespace/>
            </ros>
            <max_velocity>0.2</max_velocity>
            <publish_rate>10</publish_rate>
          </plugin>
        </gazebo>
      </model>

</sdf>